Workbook

Sheet Valuation
B2: ='2. Basics'!D2 -> Docty Health Care India Private Limited
B3: Valuation Of the company without Corporate Wellness & Market Place
B6: Year | C6: 1 | D6: =C6+1 -> 2 | E6: =D6+1 -> 3 | F6: =E6+1 -> 4 | G6: =F6+1 -> 5 | H6: =G6+1 -> 6
B7: Particulars | C7: ='1. P&L (Only CR)'!B7 -> 2025 | D7: ='1. P&L (Only CR)'!C7 -> 2026 | E7: ='1. P&L (Only CR)'!D7 -> 2027 | F7: ='1. P&L (Only CR)'!E7 -> 2028 | G7: ='1. P&L (Only CR)'!F7 -> 2029 | H7: ='1. P&L (Only CR)'!G7 -> 2030
B8: EAT | C8: ='1. P&L (Only CR)'!B41 -> #VALUE! | D8: ='1. P&L (Only CR)'!C41 -> #VALUE! | E8: ='1. P&L (Only CR)'!D41 -> #VALUE! | F8: ='1. P&L (Only CR)'!E41 -> #VALUE! | G8: ='1. P&L (Only CR)'!F41 -> #VALUE! | H8: ='1. P&L (Only CR)'!G41 -> #VALUE!
B9: Add: Depreciation | C9: ='1. P&L (Only CR)'!B36 -> 3531770 | D9: ='1. P&L (Only CR)'!C36 -> 12069046 | E9: ='1. P&L (Only CR)'!D36 -> 9437782.2 | F9: ='1. P&L (Only CR)'!E36 -> 7425803.1 | G9: ='1. P&L (Only CR)'!F36 -> 5884008.2 | H9: ='1. P&L (Only CR)'!G36 -> 4699586.8
B10: Cash from operations | C10: =C8+C9 -> #VALUE! | D10: =D8+D9 -> #VALUE! | E10: =E8+E9 -> #VALUE! | F10: =F8+F9 -> #VALUE! | G10: =G8+G9 -> #VALUE! | H10: =H8+H9 -> #VALUE!
B11: Less: Capex | C11: ='FA Schedule'!D17 -> 77650000 | D11: ='FA Schedule'!H17 -> 0 | E11: ='FA Schedule'!K17 -> 0 | F11: ='FA Schedule'!N17 -> 0 | G11: ='FA Schedule'!Q17 -> 0 | H11: ='FA Schedule'!T17 -> 0
B12: Net Operating Cash | C12: =C10-C11 -> #VALUE! | D12: =D10-D11 -> #VALUE! | E12: =E10-E11 -> #VALUE! | F12: =F10-F11 -> #VALUE! | G12: =G10-G11 -> #VALUE! | H12: =H10-H11 -> #VALUE!
B14: Discounting rate | C14: 0.15
B15: Discounting Factor | C15: =(1+$C$14)^C6 -> 1.15 | D15: =(1+$C$14)^D6 -> 1.3225 | E15: =(1+$C$14)^E6 -> 1.520875 | F15: =(1+$C$14)^F6 -> 1.7490062 | G15: =(1+$C$14)^G6 -> 2.0113572 | H15: =(1+$C$14)^H6 -> 2.3130608
B16: Present value of Cash Flows | C16: =C12/C15 -> #VALUE! | D16: =D12/D15 -> #VALUE! | E16: =E12/E15 -> #VALUE! | F16: =F12/F15 -> #VALUE! | G16: =G12/G15 -> #VALUE! | H16: =H12/H15 -> #VALUE!
B17: Growth Rate | C17: 0.05
B18: Terminal value | C18: =H16*(1+C17)/(C14-C17) -> #VALUE!
B19: Company Value | C19: =SUM(C16:H16)+C18 -> #VALUE!
B22: Total Company Value | C22: =SUM(C19:C21) -> #VALUE!
B25: =B2 -> Docty Health Care India Private Limited
B26: Valuation Of the company with Corporate Wellness & Market Place
B28: Year | C28: 1 | D28: =C28+1 -> 2 | E28: =D28+1 -> 3 | F28: =E28+1 -> 4 | G28: =F28+1 -> 5 | H28: =G28+1 -> 6
B29: Particulars | C29: =C7 -> 2025 | D29: =D7 -> 2026 | E29: =E7 -> 2027 | F29: =F7 -> 2028 | G29: =G7 -> 2029 | H29: =H7 -> 2030
B30: EAT | C30: ='1. P&L'!B43 -> #VALUE! | D30: ='1. P&L'!C43 -> #VALUE! | E30: ='1. P&L'!D43 -> #VALUE! | F30: ='1. P&L'!E43 -> #VALUE! | G30: ='1. P&L'!F43 -> #VALUE! | H30: ='1. P&L'!G43 -> #VALUE!
B31: Add: Depreciation | C31: ='1. P&L'!B38 -> 3531770 | D31: ='1. P&L'!C38 -> 12069046 | E31: ='1. P&L'!D38 -> 9437782.2 | F31: ='1. P&L'!E38 -> 7425803.1 | G31: ='1. P&L'!F38 -> 5884008.2 | H31: ='1. P&L'!G38 -> 4699586.8
B32: Cash from operations | C32: =C30+C31 -> #VALUE! | D32: =D30+D31 -> #VALUE! | E32: =E30+E31 -> #VALUE! | F32: =F30+F31 -> #VALUE! | G32: =G30+G31 -> #VALUE! | H32: =H30+H31 -> #VALUE!
B33: Less: Capex | C33: =C11 -> 77650000 | D33: =D11 -> 0 | E33: =E11 -> 0 | F33: =F11 -> 0 | G33: =G11 -> 0 | H33: =H11 -> 0
B34: Net Operating Cash | C34: =C32-C33 -> #VALUE! | D34: =D32-D33 -> #VALUE! | E34: =E32-E33 -> #VALUE! | F34: =F32-F33 -> #VALUE! | G34: =G32-G33 -> #VALUE! | H34: =H32-H33 -> #VALUE!
B36: Discounting rate | C36: =C14 -> 0.15
B37: Discounting Factor | C37: =(1+$C$36)^C28 -> 1.15 | D37: =(1+$C$36)^D28 -> 1.3225 | E37: =(1+$C$36)^E28 -> 1.520875 | F37: =(1+$C$36)^F28 -> 1.7490062 | G37: =(1+$C$36)^G28 -> 2.0113572 | H37: =(1+$C$36)^H28 -> 2.3130608
B38: Present value of Cash Flows | C38: =C34/C37 -> #VALUE! | D38: =D34/D37 -> #VALUE! | E38: =E34/E37 -> #VALUE! | F38: =F34/F37 -> #VALUE! | G38: =G34/G37 -> #VALUE! | H38: =H34/H37 -> #VALUE!
B39: Growth Rate | C39: =C17 -> 0.05
B40: Terminal value | C40: =H38*(1+C39)/(C36-C39) -> #VALUE!
B41: Company Value | C41: =SUM(C38:H38)+C40 -> #VALUE!
B42: No. of Equity shares | C42: =10000 -> 10000
B43: Fair value per Equity share | C43: =C41/C42 -> #VALUE!
B46: Total Company Value | C46: =C41 -> #VALUE!
B48: Computation of cost of capital
B49: Beta | C49: 1
B50: Risk free rate | C50: =D50/100 -> 0.0657 | D50: 6.57 | E50: 10 yr bond rate as on 30th Sep 2025
B51: Return of market | C51: =+C68 -> 0.1489
C52: 0.15
B53: Add: Company specific risk premium | C53: -
...

Sheet 1. P&L (Only CR)
A2: ='2. Basics'!D4 -> Docty Health Care India Private Limited
A4: ='2. Basics'!D6 -> Block C, Flat No.003, My Home, Hightech City, Sy No.83/1, Gachibowli, K.V.Rangareddy, Seri Lingampally, Telangana, India, 500032
A6: PROFIT & LOSS ACCOUNT FOR THE PERIOD
A7: Particulars | B7: 2025 | C7: 2026 | D7: 2027 | E7: 2028 | F7: 2029 | G7: 2030
A9: Gross Receipts
A10: Phase I
A11: ='A.I Revenue Streams - P1'!D9 -> Clinical Revenue | B11: ='B.I Sales - P1 (2)'!KK68 -> #VALUE! | C11: ='B.I Sales - P1 (2)'!KO68 -> #VALUE! | D11: ='B.I Sales - P1 (2)'!KS68 -> #VALUE! | E11: ='B.I Sales - P1 (2)'!KW68 -> #VALUE! | F11: ='B.I Sales - P1 (2)'!LA68 -> #VALUE! | G11: ='B.I Sales - P1 (2)'!LE68 -> #VALUE!
A12: ='A.I Revenue Streams - P1'!D69 -> Docty Pharma | B12: ='B.I Sales - P1 (2)'!KK78 -> 966831 | C12: ='B.I Sales - P1 (2)'!KO78 -> 42563338 | D12: ='B.I Sales - P1 (2)'!KS78 -> 2.8016689e+08 | E12: ='B.I Sales - P1 (2)'!KW78 -> 1.6641202e+09 | F12: ='B.I Sales - P1 (2)'!LA78 -> 9.7938055e+09 | G12: ='B.I Sales - P1 (2)'!LE78 -> 5.9970885e+10
A13: ='A.I Revenue Streams - P1'!D79 -> Lab & Diagnostics | B13: ='B.I Sales - P1 (2)'!KK175 -> 2123277.6 | C13: ='B.I Sales - P1 (2)'!KO175 -> 93474227 | D13: ='B.I Sales - P1 (2)'!KS175 -> 6.1528031e+08 | E13: ='B.I Sales - P1 (2)'!KW175 -> 3.6546089e+09 | F13: ='B.I Sales - P1 (2)'!LA175 -> 2.1508379e+10 | G13: ='B.I Sales - P1 (2)'!LE175 -> 1.317033e+11
A14: ='A.I Revenue Streams - P1'!D182 -> Other Services | B14: ='B.I Sales - P1 (2)'!KK192 -> 1027574.4 | C14: ='B.I Sales - P1 (2)'!KO192 -> 40514961 | D14: ='B.I Sales - P1 (2)'!KS192 -> 2.5169632e+08 | E14: ='B.I Sales - P1 (2)'!KW192 -> 1.4586208e+09 | F14: ='B.I Sales - P1 (2)'!LA192 -> 8.5250276e+09 | G14: ='B.I Sales - P1 (2)'!LE72 -> 2.5849519e+10
B15: =SUM(B11:B14) -> #VALUE! | C15: =SUM(C11:C14) -> #VALUE! | D15: =SUM(D11:D14) -> #VALUE! | E15: =SUM(E11:E14) -> #VALUE! | F15: =SUM(F11:F14) -> #VALUE! | G15: =SUM(G11:G14) -> #VALUE!
A17: Expenditure
A18: Phase - I
A19: =A.IIOPEX!D10 -> Utilities | B19: ='B.II OPEX - P1'!KJ17 -> 3590000 | C19: ='B.II OPEX - P1'!KN17 -> 40567000 | D19: ='B.II OPEX - P1'!KR17 -> 43080000 | E19: ='B.II OPEX - P1'!KV17 -> 43080000 | F19: ='B.II OPEX - P1'!KZ17 -> 43080000 | G19: ='B.II OPEX - P1'!LD17 -> 43080000
A20: =A.IIOPEX!D21 -> Salaries | B20: ='B.II OPEX - P1'!KJ28 -> 5750000 | C20: ='B.II OPEX - P1'!KN28 -> 64975000 | D20: ='B.II OPEX - P1'!KR28 -> 69000000 | E20: ='B.II OPEX - P1'!KV28 -> 69000000 | F20: ='B.II OPEX - P1'!KZ28 -> 69000000 | G20: ='B.II OPEX - P1'!LD28 -> 69000000
A21: =A.IIOPEX!D30 -> Vendor Payments | B21: ='B.II OPEX - P1'!KJ38 -> 6535178.8 | C21: ='B.II OPEX - P1'!KN38 -> 91641203 | D21: ='B.II OPEX - P1'!KR38 -> 4.4203633e+08 | E21: ='B.II OPEX - P1'!KV38 -> 2.4598324e+09 | F21: ='B.II OPEX - P1'!KZ38 -> 1.4335118e+10 | G21: ='B.II OPEX - P1'!LD38 -> 8.341874e+10
A22: =A.IIOPEX!D40 -> Supplies | B22: ='B.II OPEX - P1'!KJ47 -> 825000 | C22: ='B.II OPEX - P1'!KN47 -> 8475000 | D22: ='B.II OPEX - P1'!KR47 -> 9000000 | E22: ='B.II OPEX - P1'!KV47 -> 9000000 | F22: ='B.II OPEX - P1'!KZ47 -> 9000000 | G22: ='B.II OPEX - P1'!LD47 -> 9000000
A23: =A.IIOPEX!D49 -> Payouts | B23: ='B.II OPEX - P1'!KJ55 -> 6534000 | C23: ='B.II OPEX - P1'!KN55 -> 67122000 | D23: ='B.II OPEX - P1'!KR55 -> 71280000 | E23: ='B.II OPEX - P1'!KV55 -> 71280000 | F23: ='B.II OPEX - P1'!KZ55 -> 71280000 | G23: ='B.II OPEX - P1'!LD55 -> 71280000
A24: =A.IIOPEX!D57 -> Marketing & Promotions | B24: ='B.II OPEX - P1'!KJ63 -> 1650000 | C24: ='B.II OPEX - P1'!KN63 -> 16950000 | D24: ='B.II OPEX - P1'!KR63 -> 18000000 | E24: ='B.II OPEX - P1'!KV63 -> 18000000 | F24: ='B.II OPEX - P1'!KZ63 -> 18000000 | G24: ='B.II OPEX - P1'!LD63 -> 18000000
A25: =A.IIOPEX!D65 -> Licenses and Registration | B25: ='B.II OPEX - P1'!KJ76 -> 242000 | C25: ='B.II OPEX - P1'!KN76 -> 2486000 | D25: ='B.II OPEX - P1'!KR76 -> 2640000 | E25: ='B.II OPEX - P1'!KV76 -> 2640000 | F25: ='B.II OPEX - P1'!KZ76 -> 2640000 | G25: ='B.II OPEX - P1'!LD76 -> 2640000
A26: =A.IIOPEX!D79 -> Supplies | B26: ='B.II OPEX - P1'!KJ87 -> 0 | C26: ='B.II OPEX - P1'!KN87 -> 0 | D26: ='B.II OPEX - P1'!KR87 -> 0 | E26: ='B.II OPEX - P1'!KV87 -> 0 | F26: ='B.II OPEX - P1'!KZ87 -> 0 | G26: ='B.II OPEX - P1'!LD87 -> 0
B28: =SUM(B19:B27) -> 25126179 | C28: =SUM(C19:C27) -> 2.922162e+08 | D28: =SUM(D19:D27) -> 6.5503633e+08 | E28: =SUM(E19:E27) -> 2.6728324e+09 | F28: =SUM(F19:F27) -> 1.4548118e+10 | G28: =SUM(G19:G27) -> 8.363174e+10
A31: EBIDTA | B31: =B15-B28 -> #VALUE! | C31: =C15-C28 -> #VALUE! | D31: =D15-D28 -> #VALUE! | E31: =E15-E28 -> #VALUE! | F31: =F15-F28 -> #VALUE! | G31: =G15-G28 -> #VALUE!
B32: =B31/B15 -> #VALUE! | C32: =C31/C15 -> #VALUE! | D32: =D31/D15 -> #VALUE! | E32: =E31/E15 -> #VALUE! | F32: =F31/F15 -> #VALUE! | G32: =G31/G15 -> #VALUE!
A34: Net Profit Before Depreciation and Tax | B34: =B31-SUM(B33:B33) -> #VALUE! | C34: =C31-SUM(C33:C33) -> #VALUE! | D34: =D31-SUM(D33:D33) -> #VALUE! | E34: =E31-SUM(E33:E33) -> #VALUE! | F34: =F31-SUM(F33:F33) -> #VALUE! | G34: =G31-SUM(G33:G33) -> #VALUE!
A35: Net Profit (Before Depreciation) Ratio | B35: =B32 -> #VALUE! | C35: =C32 -> #VALUE! | D35: =D32 -> #VALUE! | E35: =E32 -> #VALUE! | F35: =F32 -> #VALUE! | G35: =G32 -> #VALUE!
A36: Depreciation | B36: ='FA Schedule'!F17 -> 3531770 | C36: ='FA Schedule'!I17 -> 12069046 | D36: ='FA Schedule'!L17 -> 9437782.2 | E36: ='FA Schedule'!O17 -> 7425803.1 | F36: ='FA Schedule'!R17 -> 5884008.2 | G36: ='FA Schedule'!U17 -> 4699586.8
A37: Net Profit After Depreciation Before Tax | B37: =B34-B36 -> #VALUE! | C37: =C34-C36 -> #VALUE! | D37: =D34-D36 -> #VALUE! | E37: =E34-E36 -> #VALUE! | F37: =F34-F36 -> #VALUE! | G37: =G34-G36 -> #VALUE!
A39: Net Profit (After Depreciation) Ratio | B39: =B$37/B15 -> #VALUE! | C39: =C$37/C15 -> #VALUE! | D39: =D$37/D15 -> #VALUE! | E39: =E$37/E15 -> #VALUE! | F39: =F$37/F15 -> #VALUE! | G39: =G$37/G15 -> #VALUE!
A40: Provision For Tax | B40: =IF(B37>0,B37*25.17%,0) -> #VALUE! | C40: =IF(C37>0,C37*25.17%,0) -> #VALUE! | D40: =IF(D37>0,D37*25.17%,0) -> #VALUE! | E40: =IF(E37>0,E37*25.17%,0) -> #VALUE! | F40: =IF(F37>0,F37*25.17%,0) -> #VALUE! | G40: =IF(G37>0,G37*25.17%,0) -> #VALUE!
A41: Net Profit After Tax | B41: =B37-B40 -> #VALUE! | C41: =C37-C40 -> #VALUE! | D41: =D37-D40 -> #VALUE! | E41: =E37-E40 -> #VALUE! | F41: =F37-F40 -> #VALUE! | G41: =G37-G40 -> #VALUE!
A48: Average Yearly turnover for the last four years | B48: =SUM(C15:G15)/COUNT(C15:G15) -> #VALUE!

Sheet 1. P&L
A2: ='2. Basics'!D4 -> Docty Health Care India Private Limited
A4: ='2. Basics'!D6 -> Block C, Flat No.003, My Home, Hightech City, Sy No.83/1, Gachibowli, K.V.Rangareddy, Seri Lingampally, Telangana, India, 500032
A6: PROFIT & LOSS ACCOUNT FOR THE PERIOD
A7: Particulars | B7: 2025 | C7: 2026 | D7: 2027 | E7: 2028 | F7: 2029 | G7: 2030
A9: Gross Receipts
A10: Phase I
A11: ='A.I Revenue Streams - P1'!D9 -> Clinical Revenue | B11: ='B.I Sales - P1 (2)'!KK68 -> #VALUE! | C11: ='B.I Sales - P1 (2)'!KO68 -> #VALUE! | D11: ='B.I Sales - P1 (2)'!KS68 -> #VALUE! | E11: ='B.I Sales - P1 (2)'!KW68 -> #VALUE! | F11: ='B.I Sales - P1 (2)'!LA68 -> #VALUE! | G11: ='B.I Sales - P1 (2)'!LE68 -> #VALUE!
A12: ='A.I Revenue Streams - P1'!D69 -> Docty Pharma | B12: ='B.I Sales - P1 (2)'!KK78 -> 966831 | C12: ='B.I Sales - P1 (2)'!KO78 -> 42563338 | D12: ='B.I Sales - P1 (2)'!KS78 -> 2.8016689e+08 | E12: ='B.I Sales - P1 (2)'!KW78 -> 1.6641202e+09 | F12: ='B.I Sales - P1 (2)'!LA78 -> 9.7938055e+09 | G12: ='B.I Sales - P1 (2)'!LE78 -> 5.9970885e+10
A13: ='A.I Revenue Streams - P1'!D79 -> Lab & Diagnostics | B13: ='B.I Sales - P1 (2)'!KK175 -> 2123277.6 | C13: ='B.I Sales - P1 (2)'!KO175 -> 93474227 | D13: ='B.I Sales - P1 (2)'!KS175 -> 6.1528031e+08 | E13: ='B.I Sales - P1 (2)'!KW175 -> 3.6546089e+09 | F13: ='B.I Sales - P1 (2)'!LA175 -> 2.1508379e+10 | G13: ='B.I Sales - P1 (2)'!LE175 -> 1.317033e+11
A14: ='A.I Revenue Streams - P1'!D176 -> Workplace Wellness | B14: ='B.I Sales - P1 (2)'!KK182 -> 0 | C14: ='B.I Sales - P1 (2)'!KO182 -> 9860267.5 | D14: ='B.I Sales - P1 (2)'!KS182 -> 21240815 | E14: ='B.I Sales - P1 (2)'!KW182 -> 31968588 | F14: ='B.I Sales - P1 (2)'!LA182 -> 42644534 | G14: ='B.I Sales - P1 (2)'!LE182 -> 34948679
A15: ='A.I Revenue Streams - P1'!D182 -> Other Services | B15: ='B.I Sales - P1 (2)'!KK192 -> 1027574.4 | C15: ='B.I Sales - P1 (2)'!KO192 -> 40514961 | D15: ='B.I Sales - P1 (2)'!KS192 -> 2.5169632e+08 | E15: ='B.I Sales - P1 (2)'!KW192 -> 1.4586208e+09 | F15: ='B.I Sales - P1 (2)'!LA192 -> 8.5250276e+09 | G15: ='B.I Sales - P1 (2)'!LE72 -> 2.5849519e+10
A16: Marketplace | B16: ='B.I Sales - P1 (2)'!KK205 -> 0 | C16: ='B.I Sales - P1 (2)'!KO205 -> 26613382 | D16: ='B.I Sales - P1 (2)'!KS205 -> 44210637 | E16: ='B.I Sales - P1 (2)'!KW205 -> 55306195 | F16: ='B.I Sales - P1 (2)'!LA205 -> 66008875 | G16: ='B.I Sales - P1 (2)'!LE73 -> 1.2407769e+10
B17: =SUM(B11:B16) -> #VALUE! | C17: =SUM(C11:C16) -> #VALUE! | D17: =SUM(D11:D16) -> #VALUE! | E17: =SUM(E11:E16) -> #VALUE! | F17: =SUM(F11:F16) -> #VALUE! | G17: =SUM(G11:G16) -> #VALUE!
D18: =D17/C17-1 -> #VALUE! | E18: =E17/D17-1 -> #VALUE! | F18: =F17/E17-1 -> #VALUE! | G18: =G17/F17-1 -> #VALUE!
A19: Expenditure
A20: Phase - I
A21: =A.IIOPEX!D10 -> Utilities | B21: ='B.II OPEX - P1'!KJ17 -> 3590000 | C21: ='B.II OPEX - P1'!KN17 -> 40567000 | D21: ='B.II OPEX - P1'!KR17 -> 43080000 | E21: ='B.II OPEX - P1'!KV17 -> 43080000 | F21: ='B.II OPEX - P1'!KZ17 -> 43080000 | G21: ='B.II OPEX - P1'!LD17 -> 43080000
A22: =A.IIOPEX!D21 -> Salaries | B22: ='B.II OPEX - P1'!KJ28 -> 5750000 | C22: ='B.II OPEX - P1'!KN28 -> 64975000 | D22: ='B.II OPEX - P1'!KR28 -> 69000000 | E22: ='B.II OPEX - P1'!KV28 -> 69000000 | F22: ='B.II OPEX - P1'!KZ28 -> 69000000 | G22: ='B.II OPEX - P1'!LD28 -> 69000000
A23: =A.IIOPEX!D30 -> Vendor Payments | B23: ='B.II OPEX - P1'!KJ38 -> 6535178.8 | C23: ='B.II OPEX - P1'!KN38 -> 91641203 | D23: ='B.II OPEX - P1'!KR38 -> 4.4203633e+08 | E23: ='B.II OPEX - P1'!KV38 -> 2.4598324e+09 | F23: ='B.II OPEX - P1'!KZ38 -> 1.4335118e+10 | G23: ='B.II OPEX - P1'!LD38 -> 8.341874e+10
A24: =A.IIOPEX!D40 -> Supplies | B24: ='B.II OPEX - P1'!KJ47 -> 825000 | C24: ='B.II OPEX - P1'!KN47 -> 8475000 | D24: ='B.II OPEX - P1'!KR47 -> 9000000 | E24: ='B.II OPEX - P1'!KV47 -> 9000000 | F24: ='B.II OPEX - P1'!KZ47 -> 9000000 | G24: ='B.II OPEX - P1'!LD47 -> 9000000
A25: =A.IIOPEX!D49 -> Payouts | B25: ='B.II OPEX - P1'!KJ55 -> 6534000 | C25: ='B.II OPEX - P1'!KN55 -> 67122000 | D25: ='B.II OPEX - P1'!KR55 -> 71280000 | E25: ='B.II OPEX - P1'!KV55 -> 71280000 | F25: ='B.II OPEX - P1'!KZ55 -> 71280000 | G25: ='B.II OPEX - P1'!LD55 -> 71280000
A26: =A.IIOPEX!D57 -> Marketing & Promotions | B26: ='B.II OPEX - P1'!KJ63 -> 1650000 | C26: ='B.II OPEX - P1'!KN63 -> 16950000 | D26: ='B.II OPEX - P1'!KR63 -> 18000000 | E26: ='B.II OPEX - P1'!KV63 -> 18000000 | F26: ='B.II OPEX - P1'!KZ63 -> 18000000 | G26: ='B.II OPEX - P1'!LD63 -> 18000000
A27: =A.IIOPEX!D65 -> Licenses and Registration | B27: ='B.II OPEX - P1'!KJ76 -> 242000 | C27: ='B.II OPEX - P1'!KN76 -> 2486000 | D27: ='B.II OPEX - P1'!KR76 -> 2640000 | E27: ='B.II OPEX - P1'!KV76 -> 2640000 | F27: ='B.II OPEX - P1'!KZ76 -> 2640000 | G27: ='B.II OPEX - P1'!LD76 -> 2640000
A28: =A.IIOPEX!D79 -> Supplies | B28: ='B.II OPEX - P1'!KJ87 -> 0 | C28: ='B.II OPEX - P1'!KN87 -> 0 | D28: ='B.II OPEX - P1'!KR87 -> 0 | E28: ='B.II OPEX - P1'!KV87 -> 0 | F28: ='B.II OPEX - P1'!KZ87 -> 0 | G28: ='B.II OPEX - P1'!LD87 -> 0
B30: =SUM(B21:B29) -> 25126179 | C30: =SUM(C21:C29) -> 2.922162e+08 | D30: =SUM(D21:D29) -> 6.5503633e+08 | E30: =SUM(E21:E29) -> 2.6728324e+09 | F30: =SUM(F21:F29) -> 1.4548118e+10 | G30: =SUM(G21:G29) -> 8.363174e+10
A33: EBIDTA | B33: =B17-B30 -> #VALUE! | C33: =C17-C30 -> #VALUE! | D33: =D17-D30 -> #VALUE! | E33: =E17-E30 -> #VALUE! | F33: =F17-F30 -> #VALUE! | G33: =G17-G30 -> #VALUE! | H33: =SUM(C33:G33)/5 -> #VALUE!
B34: =B33/B17 -> #VALUE! | C34: =C33/C17 -> #VALUE! | D34: =D33/D17 -> #VALUE! | E34: =E33/E17 -> #VALUE! | F34: =F33/F17 -> #VALUE! | G34: =G33/G17 -> #VALUE!
A36: Net Profit Before Depreciation and Tax | B36: =B33-SUM(B35:B35) -> #VALUE! | C36: =C33-SUM(C35:C35) -> #VALUE! | D36: =D33-SUM(D35:D35) -> #VALUE! | E36: =E33-SUM(E35:E35) -> #VALUE! | F36: =F33-SUM(F35:F35) -> #VALUE! | G36: =G33-SUM(G35:G35) -> #VALUE!
A37: Net Profit (Before Depreciation) Ratio | B37: =B34 -> #VALUE! | C37: =C34 -> #VALUE! | D37: =D34 -> #VALUE! | E37: =E34 -> #VALUE! | F37: =F34 -> #VALUE! | G37: =G34 -> #VALUE!
A38: Depreciation | B38: ='FA Schedule'!F17 -> 3531770 | C38: ='FA Schedule'!I17 -> 12069046 | D38: ='FA Schedule'!L17 -> 9437782.2 | E38: ='FA Schedule'!O17 -> 7425803.1 | F38: ='FA Schedule'!R17 -> 5884008.2 | G38: ='FA Schedule'!U17 -> 4699586.8
A39: Net Profit After Depreciation Before Tax | B39: =B36-B38 -> #VALUE! | C39: =C36-C38 -> #VALUE! | D39: =D36-D38 -> #VALUE! | E39: =E36-E38 -> #VALUE! | F39: =F36-F38 -> #VALUE! | G39: =G36-G38 -> #VALUE!
A41: Net Profit (After Depreciation) Ratio | B41: =B$39/B17 -> #VALUE! | C41: =C$39/C17 -> #VALUE! | D41: =D$39/D17 -> #VALUE! | E41: =E$39/E17 -> #VALUE! | F41: =F$39/F17 -> #VALUE! | G41: =G$39/G17 -> #VALUE!
A42: Provision For Tax | B42: =IF(B39>0,B39*25.17%,0) -> #VALUE! | C42: =IF(C39>0,C39*25.17%,0) -> #VALUE! | D42: =IF(D39>0,D39*25.17%,0) -> #VALUE! | E42: =IF(E39>0,E39*25.17%,0) -> #VALUE! | F42: =IF(F39>0,F39*25.17%,0) -> #VALUE! | G42: =IF(G39>0,G39*25.17%,0) -> #VALUE!
A43: Net Profit After Tax | B43: =B39-B42 -> #VALUE! | C43: =C39-C42 -> #VALUE! | D43: =D39-D42 -> #VALUE! | E43: =E39-E42 -> #VALUE! | F43: =F39-F42 -> #VALUE! | G43: =G39-G42 -> #VALUE!
D44: =D43/D17*100 -> #VALUE! | E44: =E43/E17*100 -> #VALUE! | F44: =F43/F17*100 -> #VALUE! | G44: =G43/G17*100 -> #VALUE!
A50: Average Yearly turnover for the last four years | B50: =SUM(C17:G17)/COUNT(C17:G17) -> #VALUE!

Sheet 2. Basics
B2: 1 | C2: Legal Name of the Business | D2: Docty Health Care India Private Limited
B4: 2 | C4: Trade Name of the Business | D4: =D2 -> Docty Health Care India Private Limited
B6: 3 | C6: Registered Office Address | D6: Block C, Flat No.003, My Home, Hightech City, Sy No.83/1, Gachibowli, K.V.Rangareddy, Seri Lingampally, Telangana, India, 500032
B8: 4 | C8: Official Email Id | D8: lakshman@docty.ai
B10: 5 | C10: Official Contact Number | D10: 7305961978
B12: 6 | C12: Details of the Promoter | D12: Bennebathula Varhala Babu, Venkataratnam Kamala Bai
B14: 6.a | C14: Total number of Promoters | D14: 2
B16: 7 | C16: Tentative Start Date of the project Phase 1 | D16: 45870 | E16: DD/MM/YYYY
B18: 8 | C18: Company Description | D18: Docty positions itself as the India arm of the global telehealth and digital healthcare platform Docty Healthcare, which was incorporated in 2020. The company describes its offering as a “360-degree digital healthcare solution.” It is developing an online platform that enables users to consult doctors via telemedicine, order medicines online, book home lab tests, and more. In addition, Docty offers corporate wellness packages designed to support employee health and well-being.
B20: 9 | C20: No. of Equity Share of the Company | D20: 10000
B22: 10 | C22: Face value of equity shares | D22: 10
B24: 11 | C24: Paid up Share Capital | D24: 100000

Sheet A.I Revenue Streams - P1
C2: Revenue Streams
C3: This Sheet assists us in getting the data related to Sales
C5: PHASE - 1 | F5: ='2. Basics'!D16 -> 45870 | L5: Y2
H6: No. of branches | L6: 2026-27 | N6: 2027-28 | P6: 2028-29 | R6: 2029-30 | T6: 2030-31 | V6: 2031-32
H7: 1
D8: Revenue Streams | E8: Sub Stream | F8: Products | H8: Number of Products sold per month | J8: Sale Price of each product | L8: Monthly Growth Rate in Y2 | N8: Yearly Growth Rate from Y2 to Y3 | P8: Yearly Growth Rate from Y3 to Y4 | R8: Yearly Growth Rate from Y4 to Y5 | T8: Yearly Growth Rate from Y5 to Y6 | V8: Yearly Growth Rate from Y6 to Y7 | AI8: =AE8+IF(AI3='A.I Revenue Streams - P1'!H9
C9: 1 | D9: Clinical Revenue | E9: Dental
C10: 1a | F10: Root Canal | H10: =2*4*H7 -> 8 | J10: Q | L10: 0.25 | N10: 0.2 | P10: 0.1 | R10: 0.1 | T10: 0.15 | V10: 0.01
C11: 1b | F11: Teeth Extraction | H11: =2*4*H7 -> 8 | J11: 1500 | L11: 0.25 | N11: 0.2 | P11: 0.1 | R11: 0.1 | T11: 0.15 | V11: 0.01
C12: 1c | F12: Wisdom tooth Removal | H12: =1*4*H7 -> 4 | J12: 5500 | L12: 0.25 | N12: 0.2 | P12: 0.1 | R12: 0.1 | T12: 0.15 | V12: 0.01
C13: 1d | F13: Implant | H13: =2*H7 -> 2 | J13: 22000 | L13: 0.25 | N13: 0.2 | P13: 0.1 | R13: 0.1 | T13: 0.15 | V13: 0.01
F14: X Ray | H14: =10*30*H7 -> 300 | J14: 300 | L14: 0.25 | N14: 0.2 | P14: 0.1 | R14: 0.1 | T14: 0.15 | V14: 0.01
F15: Scaling | H15: =2*4*H7 -> 8 | J15: 1800 | L15: 0.25 | N15: 0.2 | P15: 0.1 | R15: 0.1 | T15: 0.15 | V15: 0.01
F16: Flap Surgery | H16: =1*H7 -> 1 | J16: 33000 | L16: 0.25 | N16: 0.2 | P16: 0.1 | R16: 0.1 | T16: 0.15 | V16: 0.01
F17: Curetta (2-3 teeth) | H17: =4*H7 -> 4 | J17: 3700 | L17: 0.25 | N17: 0.2 | P17: 0.1 | R17: 0.1 | T17: 0.15 | V17: 0.01
F18: Complete Denture | H18: =0.5*H7 -> 0.5 | J18: 30000 | L18: 0.25 | N18: 0.2 | P18: 0.1 | R18: 0.1 | T18: 0.15 | V18: 0.01
F19: Comple Denture (BPS Denture) | H19: =0.5*H7 -> 0.5 | J19: 47000 | L19: 0.25 | N19: 0.2 | P19: 0.1 | R19: 0.1 | T19: 0.15 | V19: 0.01
F20: Removable Partial Denture | H20: =2*H7 -> 2 | J20: 1500 | L20: 0.25 | N20: 0.2 | P20: 0.1 | R20: 0.1 | T20: 0.15 | V20: 0.01
F21: Filling | H21: =2*30*H7 -> 60 | J21: 1500 | L21: 0.25 | N21: 0.2 | P21: 0.1 | R21: 0.1 | T21: 0.15 | V21: 0.01
F22: Crowns | H22: =4*H7 -> 4 | J22: 5000 | L22: 0.25 | N22: 0.2 | P22: 0.1 | R22: 0.1 | T22: 0.15 | V22: 0.01
F23: Crowns Zircornia | H23: =4*H7 -> 4 | J23: 10000 | L23: 0.25 | N23: 0.2 | P23: 0.1 | R23: 0.1 | T23: 0.15 | V23: 0.01
F24: Bruxzir (Lifetime) | H24: =1*H7 -> 1 | J24: 20000 | L24: 0.25 | N24: 0.2 | P24: 0.1 | R24: 0.1 | T24: 0.15 | V24: 0.01
F25: Metal Braces | H25: =0.25*H7 -> 0.25 | J25: 30000 | L25: 0.25 | N25: 0.2 | P25: 0.1 | R25: 0.1 | T25: 0.15 | V25: 0.01
F26: Ceramics Braces | H26: =0.25*H7 -> 0.25 | J26: 45000 | L26: 0.25 | N26: 0.2 | P26: 0.1 | R26: 0.1 | T26: 0.15 | V26: 0.01
F27: Metal Braces(Self Ligating) | H27: =0.25*H7 -> 0.25 | J27: 55000 | L27: 0.25 | N27: 0.2 | P27: 0.1 | R27: 0.1 | T27: 0.15 | V27: 0.01
F28: Ceramics Braces (Self Ligating) | H28: =0.25*H7 -> 0.25 | J28: 65000 | L28: 0.25 | N28: 0.2 | P28: 0.1 | R28: 0.1 | T28: 0.15 | V28: 0.01
L29: 0.25 | N29: 0.2 | P29: 0.1 | R29: 0.1 | T29: 0.15 | V29: 0.01
E30: General Physician | L30: 0.25 | N30: 0.2 | P30: 0.1 | R30: 0.1 | T30: 0.15 | V30: 0.01
F31: Consultation | H31: =20*30*H7 -> 600 | J31: 500 | L31: 0.25 | N31: 0.2 | P31: 0.1 | R31: 0.1 | T31: 0.15 | V31: 0.01
F32: Medical Certificate | H32: =30*H7 -> 30 | J32: 300 | L32: 0.25 | N32: 0.2 | P32: 0.1 | R32: 0.1 | T32: 0.15 | V32: 0.01
F33: Fit to Fly Certificate | H33: =2*H7 -> 2 | J33: 300 | L33: 0.25 | N33: 0.2 | P33: 0.1 | R33: 0.1 | T33: 0.15 | V33: 0.01
L34: 0.25 | N34: 0.2 | P34: 0.1 | R34: 0.1 | T34: 0.15 | V34: 0.01
E35: Physio | L35: 0.25 | N35: 0.2 | P35: 0.1 | R35: 0.1 | T35: 0.15 | V35: 0.01
F36: Excercises | H36: =1*30*H7 -> 30 | J36: 500 | L36: 0.25 | N36: 0.2 | P36: 0.1 | R36: 0.1 | T36: 0.15 | V36: 0.01
F37: Interferentail Therapy(IFT)-Single | H37: =30*H7 -> 30 | J37: 700 | L37: 0.25 | N37: 0.2 | P37: 0.1 | R37: 0.1 | T37: 0.15 | V37: 0.01
F38: Interferentail Therapy(IFT)-Standard package | H38: =2*4*H7 -> 8 | J38: 3000 | L38: 0.25 | N38: 0.2 | P38: 0.1 | R38: 0.1 | T38: 0.15 | V38: 0.01
F39: Interferentail Therapy(IFT)-Advance package | H39: =2*4*H7 -> 8 | J39: 5500 | L39: 0.25 | N39: 0.2 | P39: 0.1 | R39: 0.1 | T39: 0.15 | V39: 0.01
F40: Ultrasound Therapy (UST) - Single | H40: =30*H7 -> 30 | J40: 600 | L40: 0.25 | N40: 0.2 | P40: 0.1 | R40: 0.1 | T40: 0.15 | V40: 0.01
F41: Ultrasound Therapy (UST) - Standard Package | H41: =2*4*H7 -> 8 | J41: 3000 | L41: 0.25 | N41: 0.2 | P41: 0.1 | R41: 0.1 | T41: 0.15 | V41: 0.01
F42: Ultrasound Therapy (UST) - Advance Package | H42: =2*4*H7 -> 8 | J42: 5500 | L42: 0.25 | N42: 0.2 | P42: 0.1 | R42: 0.1 | T42: 0.15 | V42: 0.01
...

Sheet Branch
B2: Sl. No. | C2: Year | D2: Month | E2: Number of Branches | F2: Growth | G2: Addition of branches | J2: Subscriptions Market Place | K2: Subscriptions Retail | L2: Subscriptions Corporate | M2: Cummulative Market Place | N2: Cummulative Subs Retail | O2: Cummulative Subs Corporate
B3: Start Date | C3: =IF(MONTH(D3)<=3,TEXT(D3,"yyyy")-1 & "-" & TEXT(D3,"yy"),IF(MONTH(D3)>3,TEXT(D3,"yyyy") & "-" & TEXT(D3,"yy")+1)) -> 2025-26 | D3: =EOMONTH('2. Basics'!$D$16,1) -> 45930 | G3: 1
B4: 1 | C4: =IF(MONTH(D4)<=3,TEXT(D4,"yyyy")-1 & "-" & TEXT(D4,"yy"),IF(MONTH(D4)>3,TEXT(D4,"yyyy") & "-" & TEXT(D4,"yy")+1)) -> 2025-26 | D4: =EOMONTH($D$3,B4) -> 45961 | E4: 3 | F4: 0.15 | G4: 2 | H4: 0.15 | K4: 60 | N4: =K4 -> 60
B5: 2 | C5: =IF(MONTH(D5)<=3,TEXT(D5,"yyyy")-1 & "-" & TEXT(D5,"yy"),IF(MONTH(D5)>3,TEXT(D5,"yyyy") & "-" & TEXT(D5,"yy")+1)) -> 2025-26 | D5: =EOMONTH($D$3,B5) -> 45991 | E5: 3 | F5: 0.15 | G5: =E5-E4 -> 0 | H5: 0.1 | K5: 75 | N5: =K5 -> 75
B6: 3 | C6: =IF(MONTH(D6)<=3,TEXT(D6,"yyyy")-1 & "-" & TEXT(D6,"yy"),IF(MONTH(D6)>3,TEXT(D6,"yyyy") & "-" & TEXT(D6,"yy")+1)) -> 2025-26 | D6: =EOMONTH($D$3,B6) -> 46022 | E6: 4 | F6: 0.15 | G6: =E6-E5 -> 1 | H6: 0.15 | K6: 100 | N6: =K6 -> 100
B7: 4 | C7: =IF(MONTH(D7)<=3,TEXT(D7,"yyyy")-1 & "-" & TEXT(D7,"yy"),IF(MONTH(D7)>3,TEXT(D7,"yyyy") & "-" & TEXT(D7,"yy")+1)) -> 2025-26 | D7: =EOMONTH($D$3,B7) -> 46053 | E7: 5 | F7: 0.15 | G7: =E7-E6 -> 1 | H7: 0 | J7: 50 | K7: 130 | L7: 1000 | M7: =J7 -> 50 | N7: =K7 -> 130 | O7: =L7 -> 1000
B8: 5 | C8: =IF(MONTH(D8)<=3,TEXT(D8,"yyyy")-1 & "-" & TEXT(D8,"yy"),IF(MONTH(D8)>3,TEXT(D8,"yyyy") & "-" & TEXT(D8,"yy")+1)) -> 2025-26 | D8: =EOMONTH($D$3,B8) -> 46081 | E8: 8 | F8: 0.15 | G8: =E8-E7 -> 3 | H8: 0 | J8: 80 | K8: 180 | L8: 1000 | M8: =J8 -> 80 | N8: =K8 -> 180 | O8: =L8 -> 1000
B9: 6 | C9: =IF(MONTH(D9)<=3,TEXT(D9,"yyyy")-1 & "-" & TEXT(D9,"yy"),IF(MONTH(D9)>3,TEXT(D9,"yyyy") & "-" & TEXT(D9,"yy")+1)) -> 2025-26 | D9: =EOMONTH($D$3,B9) -> 46112 | E9: 10 | F9: 0.15 | G9: =E9-E8 -> 2 | H9: 0 | J9: 100 | K9: 230 | L9: 1000 | M9: =J9 -> 100 | N9: =K9 -> 230 | O9: =L9 -> 1000
B10: 7 | C10: =IF(MONTH(D10)<=3,TEXT(D10,"yyyy")-1 & "-" & TEXT(D10,"yy"),IF(MONTH(D10)>3,TEXT(D10,"yyyy") & "-" & TEXT(D10,"yy")+1)) -> 2026-27 | D10: =EOMONTH($D$3,B10) -> 46142 | E10: 10 | F10: 0.15 | G10: =E10-E9 -> 0 | H10: 0 | J10: 150 | K10: 300 | L10: 1200 | M10: =J10 -> 150 | N10: =K10 -> 300 | O10: =L10 -> 1200
B11: 8 | C11: =IF(MONTH(D11)<=3,TEXT(D11,"yyyy")-1 & "-" & TEXT(D11,"yy"),IF(MONTH(D11)>3,TEXT(D11,"yyyy") & "-" & TEXT(D11,"yy")+1)) -> 2026-27 | D11: =EOMONTH($D$3,B11) -> 46173 | E11: 10 | F11: 0.15 | G11: =E11-E10 -> 0 | H11: 0 | J11: 200 | K11: 340 | L11: 1200 | M11: =J11 -> 200 | N11: =K11 -> 340 | O11: =L11 -> 1200
B12: 9 | C12: =IF(MONTH(D12)<=3,TEXT(D12,"yyyy")-1 & "-" & TEXT(D12,"yy"),IF(MONTH(D12)>3,TEXT(D12,"yyyy") & "-" & TEXT(D12,"yy")+1)) -> 2026-27 | D12: =EOMONTH($D$3,B12) -> 46203 | E12: 10 | F12: 0.15 | G12: =E12-E11 -> 0 | H12: 0 | J12: 250 | K12: 385 | L12: 1200 | M12: =J12 -> 250 | N12: =K12 -> 385 | O12: =L12 -> 1200
B13: 10 | C13: =IF(MONTH(D13)<=3,TEXT(D13,"yyyy")-1 & "-" & TEXT(D13,"yy"),IF(MONTH(D13)>3,TEXT(D13,"yyyy") & "-" & TEXT(D13,"yy")+1)) -> 2026-27 | D13: =EOMONTH($D$3,B13) -> 46234 | E13: 10 | F13: 0.15 | G13: =E13-E12 -> 0 | H13: 0 | J13: 300 | K13: 420 | L13: 1500 | M13: =J13 -> 300 | N13: =K13 -> 420 | O13: =L13 -> 1500
B14: 11 | C14: =IF(MONTH(D14)<=3,TEXT(D14,"yyyy")-1 & "-" & TEXT(D14,"yy"),IF(MONTH(D14)>3,TEXT(D14,"yyyy") & "-" & TEXT(D14,"yy")+1)) -> 2026-27 | D14: =EOMONTH($D$3,B14) -> 46265 | E14: 10 | F14: 0.15 | G14: =E14-E13 -> 0 | H14: 0 | J14: 350 | K14: 450 | L14: 1500 | M14: =J14 -> 350 | N14: =K14 -> 450 | O14: =L14 -> 1500
B15: 12 | C15: =IF(MONTH(D15)<=3,TEXT(D15,"yyyy")-1 & "-" & TEXT(D15,"yy"),IF(MONTH(D15)>3,TEXT(D15,"yyyy") & "-" & TEXT(D15,"yy")+1)) -> 2026-27 | D15: =EOMONTH($D$3,B15) -> 46295 | E15: 10 | F15: 0.15 | G15: =E15-E14 -> 0 | H15: 0 | J15: 400 | K15: 500 | L15: 1500 | M15: =J15 -> 400 | N15: =K15 -> 500 | O15: =L15 -> 1500
B16: 13 | C16: =IF(MONTH(D16)<=3,TEXT(D16,"yyyy")-1 & "-" & TEXT(D16,"yy"),IF(MONTH(D16)>3,TEXT(D16,"yyyy") & "-" & TEXT(D16,"yy")+1)) -> 2026-27 | D16: =EOMONTH($D$3,B16) -> 46326 | E16: 10 | F16: 0.15 | G16: =E16-E15 -> 0 | H16: 0 | J16: 450 | K16: 500 | L16: 1800 | M16: =J16 -> 450 | N16: =K16 -> 500 | O16: =L16 -> 1800
B17: 14 | C17: =IF(MONTH(D17)<=3,TEXT(D17,"yyyy")-1 & "-" & TEXT(D17,"yy"),IF(MONTH(D17)>3,TEXT(D17,"yyyy") & "-" & TEXT(D17,"yy")+1)) -> 2026-27 | D17: =EOMONTH($D$3,B17) -> 46356 | E17: 10 | F17: 0.15 | G17: =E17-E16 -> 0 | H17: 0 | J17: 500 | K17: 500 | L17: 1800 | M17: =J17 -> 500 | N17: =K17 -> 500 | O17: =L17 -> 1800
B18: 15 | C18: =IF(MONTH(D18)<=3,TEXT(D18,"yyyy")-1 & "-" & TEXT(D18,"yy"),IF(MONTH(D18)>3,TEXT(D18,"yyyy") & "-" & TEXT(D18,"yy")+1)) -> 2026-27 | D18: =EOMONTH($D$3,B18) -> 46387 | E18: 10 | F18: 0.15 | G18: =E18-E17 -> 0 | H18: 0 | J18: 500 | K18: 500 | L18: 1800 | M18: =J18 -> 500 | N18: =K18 -> 500 | O18: =L18 -> 1800
B19: 16 | C19: =IF(MONTH(D19)<=3,TEXT(D19,"yyyy")-1 & "-" & TEXT(D19,"yy"),IF(MONTH(D19)>3,TEXT(D19,"yyyy") & "-" & TEXT(D19,"yy")+1)) -> 2026-27 | D19: =EOMONTH($D$3,B19) -> 46418 | E19: 10 | F19: 0.15 | G19: =E19-E18 -> 0 | H19: 0 | J19: 500 | K19: 500 | L19: 2100 | M19: =J19+J7 -> 550 | N19: =K19+K7 -> 630 | O19: =(L19+L7) -> 3100
B20: 17 | C20: =IF(MONTH(D20)<=3,TEXT(D20,"yyyy")-1 & "-" & TEXT(D20,"yy"),IF(MONTH(D20)>3,TEXT(D20,"yyyy") & "-" & TEXT(D20,"yy")+1)) -> 2026-27 | D20: =EOMONTH($D$3,B20) -> 46446 | E20: 10 | F20: 0.15 | G20: =E20-E19 -> 0 | H20: 0 | J20: 500 | K20: 500 | L20: 2100 | M20: =J20+J8 -> 580 | N20: =K20+K8 -> 680 | O20: =(L20+L8) -> 3100
B21: 18 | C21: =IF(MONTH(D21)<=3,TEXT(D21,"yyyy")-1 & "-" & TEXT(D21,"yy"),IF(MONTH(D21)>3,TEXT(D21,"yyyy") & "-" & TEXT(D21,"yy")+1)) -> 2026-27 | D21: =EOMONTH($D$3,B21) -> 46477 | E21: 10 | F21: 0.15 | G21: =E21-E20 -> 0 | H21: 0 | J21: 500 | K21: 500 | L21: 2100 | M21: =J21+J9 -> 600 | N21: =K21+K9 -> 730 | O21: =(L21+L9) -> 3100
B22: 19 | C22: =IF(MONTH(D22)<=3,TEXT(D22,"yyyy")-1 & "-" & TEXT(D22,"yy"),IF(MONTH(D22)>3,TEXT(D22,"yyyy") & "-" & TEXT(D22,"yy")+1)) -> 2027-28 | D22: =EOMONTH($D$3,B22) -> 46507 | E22: 10 | F22: 0.15 | G22: =E22-E21 -> 0 | H22: 0 | J22: 500 | K22: 500 | L22: 2100 | M22: =J22+J10 -> 650 | N22: =K22+K10 -> 800 | O22: =(L22+L10) -> 3300
B23: 20 | C23: =IF(MONTH(D23)<=3,TEXT(D23,"yyyy")-1 & "-" & TEXT(D23,"yy"),IF(MONTH(D23)>3,TEXT(D23,"yyyy") & "-" & TEXT(D23,"yy")+1)) -> 2027-28 | D23: =EOMONTH($D$3,B23) -> 46538 | E23: 10 | F23: 0.15 | G23: =E23-E22 -> 0 | H23: 0 | J23: 500 | K23: 500 | L23: 2100 | M23: =J23+J11 -> 700 | N23: =K23+K11 -> 840 | O23: =(L23+L11) -> 3300
B24: 21 | C24: =IF(MONTH(D24)<=3,TEXT(D24,"yyyy")-1 & "-" & TEXT(D24,"yy"),IF(MONTH(D24)>3,TEXT(D24,"yyyy") & "-" & TEXT(D24,"yy")+1)) -> 2027-28 | D24: =EOMONTH($D$3,B24) -> 46568 | E24: 10 | F24: 0.15 | G24: =E24-E23 -> 0 | H24: 0 | J24: 500 | K24: 500 | L24: 2100 | M24: =J24+J12 -> 750 | N24: =K24+K12 -> 885 | O24: =(L24+L12) -> 3300
B25: 22 | C25: =IF(MONTH(D25)<=3,TEXT(D25,"yyyy")-1 & "-" & TEXT(D25,"yy"),IF(MONTH(D25)>3,TEXT(D25,"yyyy") & "-" & TEXT(D25,"yy")+1)) -> 2027-28 | D25: =EOMONTH($D$3,B25) -> 46599 | E25: 10 | F25: 0.15 | G25: =E25-E24 -> 0 | H25: 0 | J25: 500 | K25: 500 | L25: 2100 | M25: =J25+J13 -> 800 | N25: =K25+K13 -> 920 | O25: =(L25+L13) -> 3600
B26: 23 | C26: =IF(MONTH(D26)<=3,TEXT(D26,"yyyy")-1 & "-" & TEXT(D26,"yy"),IF(MONTH(D26)>3,TEXT(D26,"yyyy") & "-" & TEXT(D26,"yy")+1)) -> 2027-28 | D26: =EOMONTH($D$3,B26) -> 46630 | E26: 10 | F26: 0.15 | G26: =E26-E25 -> 0 | H26: 0 | J26: 500 | K26: 500 | L26: 2100 | M26: =J26+J14 -> 850 | N26: =K26+K14 -> 950 | O26: =(L26+L14) -> 3600
B27: 24 | C27: =IF(MONTH(D27)<=3,TEXT(D27,"yyyy")-1 & "-" & TEXT(D27,"yy"),IF(MONTH(D27)>3,TEXT(D27,"yyyy") & "-" & TEXT(D27,"yy")+1)) -> 2027-28 | D27: =EOMONTH($D$3,B27) -> 46660 | E27: 10 | F27: 0.15 | G27: =E27-E26 -> 0 | H27: 0 | J27: 500 | K27: 500 | L27: 2100 | M27: =J27+J15 -> 900 | N27: =K27+K15 -> 1000 | O27: =(L27+L15) -> 3600
B28: 25 | C28: =IF(MONTH(D28)<=3,TEXT(D28,"yyyy")-1 & "-" & TEXT(D28,"yy"),IF(MONTH(D28)>3,TEXT(D28,"yyyy") & "-" & TEXT(D28,"yy")+1)) -> 2027-28 | D28: =EOMONTH($D$3,B28) -> 46691 | E28: 10 | F28: 0.15 | G28: =E28-E27 -> 0 | H28: 0 | J28: 500 | K28: 500 | L28: 2100 | M28: =J28+J16 -> 950 | N28: =K28+K16 -> 1000 | O28: =(L28+L16) -> 3900
B29: 26 | C29: =IF(MONTH(D29)<=3,TEXT(D29,"yyyy")-1 & "-" & TEXT(D29,"yy"),IF(MONTH(D29)>3,TEXT(D29,"yyyy") & "-" & TEXT(D29,"yy")+1)) -> 2027-28 | D29: =EOMONTH($D$3,B29) -> 46721 | E29: 10 | F29: 0.15 | G29: =E29-E28 -> 0 | H29: 0 | J29: 500 | K29: 500 | L29: 2100 | M29: =J29+J17 -> 1000 | N29: =K29+K17 -> 1000 | O29: =(L29+L17) -> 3900
B30: 27 | C30: =IF(MONTH(D30)<=3,TEXT(D30,"yyyy")-1 & "-" & TEXT(D30,"yy"),IF(MONTH(D30)>3,TEXT(D30,"yyyy") & "-" & TEXT(D30,"yy")+1)) -> 2027-28 | D30: =EOMONTH($D$3,B30) -> 46752 | E30: 10 | F30: 0.15 | G30: =E30-E29 -> 0 | H30: 0 | J30: 500 | K30: 500 | L30: 2100 | M30: =J30+J18 -> 1000 | N30: =K30+K18 -> 1000 | O30: =(L30+L18) -> 3900
B31: 28 | C31: =IF(MONTH(D31)<=3,TEXT(D31,"yyyy")-1 & "-" & TEXT(D31,"yy"),IF(MONTH(D31)>3,TEXT(D31,"yyyy") & "-" & TEXT(D31,"yy")+1)) -> 2027-28 | D31: =EOMONTH($D$3,B31) -> 46783 | E31: 10 | F31: 0.15 | G31: =E31-E30 -> 0 | H31: 0 | J31: 500 | K31: 500 | L31: 2100 | M31: =J31+J19+J7 -> 1050 | N31: =K31+K19+K7 -> 1130 | O31: =L31+L19+L7 -> 5200
B32: 29 | C32: =IF(MONTH(D32)<=3,TEXT(D32,"yyyy")-1 & "-" & TEXT(D32,"yy"),IF(MONTH(D32)>3,TEXT(D32,"yyyy") & "-" & TEXT(D32,"yy")+1)) -> 2027-28 | D32: =EOMONTH($D$3,B32) -> 46812 | E32: 10 | F32: 0.15 | G32: =E32-E31 -> 0 | H32: 0 | J32: 500 | K32: 500 | L32: 2100 | M32: =J32+J20+J8 -> 1080 | N32: =K32+K20+K8 -> 1180 | O32: =L32+L20+L8 -> 5200
B33: 30 | C33: =IF(MONTH(D33)<=3,TEXT(D33,"yyyy")-1 & "-" & TEXT(D33,"yy"),IF(MONTH(D33)>3,TEXT(D33,"yyyy") & "-" & TEXT(D33,"yy")+1)) -> 2027-28 | D33: =EOMONTH($D$3,B33) -> 46843 | E33: 10 | F33: 0.15 | G33: =E33-E32 -> 0 | H33: 0 | J33: 500 | K33: 500 | L33: 2100 | M33: =J33+J21+J9 -> 1100 | N33: =K33+K21+K9 -> 1230 | O33: =L33+L21+L9 -> 5200
B34: 31 | C34: =IF(MONTH(D34)<=3,TEXT(D34,"yyyy")-1 & "-" & TEXT(D34,"yy"),IF(MONTH(D34)>3,TEXT(D34,"yyyy") & "-" & TEXT(D34,"yy")+1)) -> 2028-29 | D34: =EOMONTH($D$3,B34) -> 46873 | E34: 10 | F34: 0.15 | G34: =E34-E33 -> 0 | H34: 0 | J34: 500 | K34: 500 | L34: 2100 | M34: =J34+J22+J10 -> 1150 | N34: =K34+K22+K10 -> 1300 | O34: =L34+L22+L10 -> 5400
B35: 32 | C35: =IF(MONTH(D35)<=3,TEXT(D35,"yyyy")-1 & "-" & TEXT(D35,"yy"),IF(MONTH(D35)>3,TEXT(D35,"yyyy") & "-" & TEXT(D35,"yy")+1)) -> 2028-29 | D35: =EOMONTH($D$3,B35) -> 46904 | E35: 10 | F35: 0.15 | G35: =E35-E34 -> 0 | H35: 0 | J35: 500 | K35: 500 | L35: 2100 | M35: =J35+J23+J11 -> 1200 | N35: =K35+K23+K11 -> 1340 | O35: =L35+L23+L11 -> 5400
B36: 33 | C36: =IF(MONTH(D36)<=3,TEXT(D36,"yyyy")-1 & "-" & TEXT(D36,"yy"),IF(MONTH(D36)>3,TEXT(D36,"yyyy") & "-" & TEXT(D36,"yy")+1)) -> 2028-29 | D36: =EOMONTH($D$3,B36) -> 46934 | E36: 10 | F36: 0.15 | G36: =E36-E35 -> 0 | H36: 0 | J36: 500 | K36: 500 | L36: 2100 | M36: =J36+J24+J12 -> 1250 | N36: =K36+K24+K12 -> 1385 | O36: =L36+L24+L12 -> 5400
B37: 34 | C37: =IF(MONTH(D37)<=3,TEXT(D37,"yyyy")-1 & "-" & TEXT(D37,"yy"),IF(MONTH(D37)>3,TEXT(D37,"yyyy") & "-" & TEXT(D37,"yy")+1)) -> 2028-29 | D37: =EOMONTH($D$3,B37) -> 46965 | E37: 10 | F37: 0.15 | G37: =E37-E36 -> 0 | H37: 0 | J37: 500 | K37: 500 | L37: 2100 | M37: =J37+J25+J13 -> 1300 | N37: =K37+K25+K13 -> 1420 | O37: =L37+L25+L13 -> 5700
B38: 35 | C38: =IF(MONTH(D38)<=3,TEXT(D38,"yyyy")-1 & "-" & TEXT(D38,"yy"),IF(MONTH(D38)>3,TEXT(D38,"yyyy") & "-" & TEXT(D38,"yy")+1)) -> 2028-29 | D38: =EOMONTH($D$3,B38) -> 46996 | E38: 10 | F38: 0.15 | G38: =E38-E37 -> 0 | H38: 0 | J38: 500 | K38: 500 | L38: 2100 | M38: =J38+J26+J14 -> 1350 | N38: =K38+K26+K14 -> 1450 | O38: =L38+L26+L14 -> 5700
B39: 36 | C39: =IF(MONTH(D39)<=3,TEXT(D39,"yyyy")-1 & "-" & TEXT(D39,"yy"),IF(MONTH(D39)>3,TEXT(D39,"yyyy") & "-" & TEXT(D39,"yy")+1)) -> 2028-29 | D39: =EOMONTH($D$3,B39) -> 47026 | E39: 10 | F39: 0.15 | G39: =E39-E38 -> 0 | H39: 0 | J39: 500 | K39: 500 | L39: 2100 | M39: =J39+J27+J15 -> 1400 | N39: =K39+K27+K15 -> 1500 | O39: =L39+L27+L15 -> 5700
B40: 37 | C40: =IF(MONTH(D40)<=3,TEXT(D40,"yyyy")-1 & "-" & TEXT(D40,"yy"),IF(MONTH(D40)>3,TEXT(D40,"yyyy") & "-" & TEXT(D40,"yy")+1)) -> 2028-29 | D40: =EOMONTH($D$3,B40) -> 47057 | E40: 10 | F40: 0.15 | G40: =E40-E39 -> 0 | H40: 0 | J40: 500 | K40: 500 | L40: 2100 | M40: =J40+J28+J16 -> 1450 | N40: =K40+K28+K16 -> 1500 | O40: =L40+L28+L16 -> 6000
B41: 38 | C41: =IF(MONTH(D41)<=3,TEXT(D41,"yyyy")-1 & "-" & TEXT(D41,"yy"),IF(MONTH(D41)>3,TEXT(D41,"yyyy") & "-" & TEXT(D41,"yy")+1)) -> 2028-29 | D41: =EOMONTH($D$3,B41) -> 47087 | E41: 10 | F41: 0.15 | G41: =E41-E40 -> 0 | H41: 0 | J41: 500 | K41: 500 | L41: 2100 | M41: =J41+J29+J17 -> 1500 | N41: =K41+K29+K17 -> 1500 | O41: =L41+L29+L17 -> 6000
...

Sheet A. Data Needed
C2: Major heads of the data needed for the business plan
D3: Hyperlink to open
B4: I | C4: We need to clearly define the Revenue Streams | D4: Nature of services. click here for the link to enter the revenue streams
B7: II | C7: Sales price per revenue streams | D7: Click
B9: III | C9: Costing headers | D9: =A.IIOPEX!C2 -> Opex, Click on the link to refer to OPEX
B11: IIV | C11: Capex Information | D11: Capex Click on the link to refer to Capex
B13: V | C13: Other Information

Sheet A.IIOPEX
C2: Opex, Click on the link to refer to OPEX
K3: No of Branches
C4: Write down all the major and nimor headers for the costing and list them here | I4: Quarter 3 | K4: 10
C5: Beside the header you will be able to write the quantity and the price | I5: Quarter 4 | K5: 20 | M5: 48 | O5: 35 | Q5: 35 | S5: 35 | U5: 35
I6: Total | K6: =K4+K5 -> 30 | M6: =K6+M5+M4 -> 78 | O6: =M6+O5+O4 -> 113 | Q6: =O6+Q5+Q4 -> 148 | S6: =Q6+S5+S4 -> 183 | U6: =S6+U5+U4 -> 218
K7: 2025-26 | M7: 2026-27 | O7: 2027-28 | Q7: 2028-29 | S7: 2029-30 | U7: 2030-31
I8: 1
D9: Major Header | E9: Sub Services | G9: Monthly | I9: Cost per month per branch | K9: Monthly Growth Rate in Y1 | M9: Yearly Growth Rate from Y1 to Y2 | O9: Yearly Growth Rate from Y2 to Y3 | Q9: Yearly Growth Rate from Y3 to Y4 | S9: Yearly Growth Rate from Y4 to Y5 | U9: Yearly Growth Rate from Y5 to Y6
C10: 1 | D10: Utilities
C11: 1a | E11: Rent | I11: =295000*I8 -> 295000 | K11: 1 | M11: 0.01 | O11: 0.01 | Q11: 0.01 | S11: 0.01 | U11: 0.01
C12: 1b | E12: Electricity | I12: 40000 | K12: 1 | M12: 0.01 | O12: 0.01 | Q12: 0.01 | S12: 0.01 | U12: 0.01
C13: 1c | E13: Internet & Telephone | I13: 4000 | K13: 1 | M13: 0.01 | O13: 0.01 | Q13: 0.01 | S13: 0.01 | U13: 0.01
C14: 1d | E14: Maintenance & Repairs | I14: 10000 | K14: 1 | M14: 0.01 | O14: 0.01 | Q14: 0.01 | S14: 0.01 | U14: 0.01
C15: 1e | E15: Petty cash expense | I15: 10000 | K15: 1 | M15: 0.01 | O15: 0.01 | Q15: 0.01 | S15: 0.01 | U15: 0.01
K16: 1 | M16: 0.01 | O16: 0.01 | Q16: 0.01 | S16: 0.01 | U16: 0.01
K17: 1 | M17: 0.01 | O17: 0.01 | Q17: 0.01 | S17: 0.01 | U17: 0.01
C18: Grand Total
C21: 2 | D21: Salaries
C22: 2a | E22: Management | I22: =200000*I8 -> 200000 | K22: 1 | M22: 0.01 | O22: 0.01 | Q22: 0.01 | S22: 0.01 | U22: 0.01
C23: 2b | E23: Doctors | I23: =150000*I8 -> 150000 | K23: 1 | M23: 0.01 | O23: 0.01 | Q23: 0.01 | S23: 0.01 | U23: 0.01
C24: 2c | E24: Clinical Staff | I24: 125000 | K24: 1 | M24: 0.01 | O24: 0.01 | Q24: 0.01 | S24: 0.01 | U24: 0.01
E25: Admin & Accounting | I25: 50000 | K25: 1 | M25: 0.01 | O25: 0.01 | Q25: 0.01 | S25: 0.01 | U25: 0.01
E26: Other Salaries | I26: 50000 | K26: 1 | M26: 0.01 | O26: 0.01 | Q26: 0.01 | S26: 0.01 | U26: 0.01
C27: Grand Total
C30: 3 | D30: Vendor Payments
C31: 3a | E31: Housekeeping | I31: =30000*I8 -> 30000 | K31: 1 | M31: 0.01 | O31: 0.01 | Q31: 0.01 | S31: 0.01 | U31: 0.01
C32: 3b | E32: Pest Control | I32: =10000*I8 -> 10000 | K32: 1 | M32: 0.01 | O32: 0.01 | Q32: 0.01 | S32: 0.01 | U32: 0.01
C33: 3c | E33: Biomedical Waste Disposal | I33: =20000/12*I8 -> 1666.6667 | K33: 1 | M33: 0.01 | O33: 0.01 | Q33: 0.01 | S33: 0.01 | U33: 0.01
C34: 3d | E34: Lab Aggregators | I34: =200000*I8 -> 200000 | K34: 1 | M34: 0.01 | O34: 0.01 | Q34: 0.01 | S34: 0.01 | U34: 0.01
G35: 5 | K35: 1 | M35: 0.01 | O35: 0.01 | Q35: 0.01 | S35: 0.01 | U35: 0.01
K36: 1 | M36: 0.01 | O36: 0.01 | Q36: 0.01 | S36: 0.01 | U36: 0.01
C37: Grand Total
C40: 4 | D40: Supplies
C41: 4a | E41: Housekeeping | I41: =10000*I8 -> 10000 | K41: 1 | M41: 0.01 | O41: 0.01 | Q41: 0.01 | S41: 0.01 | U41: 0.01
C42: 4b | E42: Clinical | I42: =50000*I8 -> 50000 | K42: 1 | M42: 0.01 | O42: 0.01 | Q42: 0.01 | S42: 0.01 | U42: 0.01
C43: 4c | E43: Pantry | I43: =10000*I8 -> 10000 | K43: 1 | M43: 0.01 | O43: 0.01 | Q43: 0.01 | S43: 0.01 | U43: 0.01
C44: 4d | E44: Admin & Office | I44: =5000*I8 -> 5000 | K44: 1 | M44: 0.01 | O44: 0.01 | Q44: 0.01 | S44: 0.01 | U44: 0.01
K45: 1 | M45: 0.01 | O45: 0.01 | Q45: 0.01 | S45: 0.01 | U45: 0.01
C46: Grand Total
C49: 5 | D49: Payouts
...

Sheet A.I Revenue Streams - P2
C2: Revenue Streams
C3: This Sheet assists us in getting the data related to Sales
C5: PHASE - 2 | E5: ='2. Basics'!D24 -> 100000
D8: Major Header | E8: Minor Header | G8: Number of Products sold per Day | I8: Sale Price of each product | K8: Monthly Growth Rate in Y1 | M8: Yearly Growth Rate from Y1 to Y2 | O8: Yearly Growth Rate from Y2 to Y3 | Q8: Yearly Growth Rate from Y3 to Y4 | S8: Yearly Growth Rate from Y4 to Y5 | U8: Yearly Growth Rate from Y5 to Y6
C9: 1 | D9: Cakes
C10: 1a | E10: Cup Cakes | G10: 5 | I10: 20 | K10: 0.1 | M10: 0.1 | O10: 0.1 | Q10: 0.1 | S10: 0.1 | U10: 0.1
C11: 1b | E11: Customised Cakes | G11: 4 | I11: 20 | K11: =$K$10 -> 0.1 | M11: =$M$10 -> 0.1 | O11: =$O$10 -> 0.1 | Q11: =$Q$10 -> 0.1 | S11: =$S$10 -> 0.1 | U11: =$U$10 -> 0.1
C12: 1c | E12: Standard Cake | G12: 3 | I12: 20 | K12: =$K$10 -> 0.1 | M12: =$M$10 -> 0.1 | O12: =$O$10 -> 0.1 | Q12: =$Q$10 -> 0.1 | S12: =$S$10 -> 0.1 | U12: =$U$10 -> 0.1
C13: 1d | E13: Cake Slices | G13: 2 | I13: 20 | K13: =$K$10 -> 0.1 | M13: =$M$10 -> 0.1 | O13: =$O$10 -> 0.1 | Q13: =$Q$10 -> 0.1 | S13: =$S$10 -> 0.1 | U13: =$U$10 -> 0.1
C14: 1e | E14: 0 | G14: 1 | I14: 20 | K14: =$K$10 -> 0.1 | M14: =$M$10 -> 0.1 | O14: =$O$10 -> 0.1 | Q14: =$Q$10 -> 0.1 | S14: =$S$10 -> 0.1 | U14: =$U$10 -> 0.1
C15: Grand Total
C18: 2 | D18: Confectionary
C19: 2a | E19: Burgers | G19: 5 | I19: 20 | K19: 0.1 | M19: 0.1 | O19: 0.1 | Q19: 0.1 | S19: 0.1 | U19: 0.1
C20: 2b | E20: Pizza | G20: 4 | I20: 20 | K20: =$K$19 -> 0.1 | M20: =$M$19 -> 0.1 | O20: =$O$19 -> 0.1 | Q20: =$Q$19 -> 0.1 | S20: =$S$19 -> 0.1 | U20: =$U$19 -> 0.1
C21: 2c | E21: Puffs | G21: 3 | I21: 20 | K21: =$K$19 -> 0.1 | M21: =$M$19 -> 0.1 | O21: =$O$19 -> 0.1 | Q21: =$Q$19 -> 0.1 | S21: =$S$19 -> 0.1 | U21: =$U$19 -> 0.1
C22: 2d | E22: Other 1 | G22: 2 | I22: 20 | K22: =$K$19 -> 0.1 | M22: =$M$19 -> 0.1 | O22: =$O$19 -> 0.1 | Q22: =$Q$19 -> 0.1 | S22: =$S$19 -> 0.1 | U22: =$U$19 -> 0.1
C23: 2e | E23: 0 | G23: 1 | I23: 20 | K23: =$K$19 -> 0.1 | M23: =$M$19 -> 0.1 | O23: =$O$19 -> 0.1 | Q23: =$Q$19 -> 0.1 | S23: =$S$19 -> 0.1 | U23: =$U$19 -> 0.1
C24: Grand Total
C27: 3 | D27: Accessorries
C28: 3a | E28: Poppers | G28: 5 | I28: 20 | K28: 0.1 | M28: 0.1 | O28: 0.1 | Q28: 0.1 | S28: 0.1 | U28: 0.1
C29: 3b | E29: Builders | G29: 4 | I29: 20 | K29: =$K$28 -> 0.1 | M29: =$M$28 -> 0.1 | O29: =$O$28 -> 0.1 | Q29: =$Q$28 -> 0.1 | S29: =$S$28 -> 0.1 | U29: =$U$28 -> 0.1
C30: 3c | E30: Blasters | G30: 3 | I30: 20 | K30: =$K$28 -> 0.1 | M30: =$M$28 -> 0.1 | O30: =$O$28 -> 0.1 | Q30: =$Q$28 -> 0.1 | S30: =$S$28 -> 0.1 | U30: =$U$28 -> 0.1
C31: 3d | E31: Decor | G31: 2 | I31: 20 | K31: =$K$28 -> 0.1 | M31: =$M$28 -> 0.1 | O31: =$O$28 -> 0.1 | Q31: =$Q$28 -> 0.1 | S31: =$S$28 -> 0.1 | U31: =$U$28 -> 0.1
C32: 3e | E32: Others | G32: 1 | I32: 20 | K32: =$K$28 -> 0.1 | M32: =$M$28 -> 0.1 | O32: =$O$28 -> 0.1 | Q32: =$Q$28 -> 0.1 | S32: =$S$28 -> 0.1 | U32: =$U$28 -> 0.1
C33: Grand Total
C36: 4 | D36: Others
C37: 4a | E37: Others 1 | G37: 5 | I37: 20 | K37: 0.1 | M37: 0.1 | O37: 0.1 | Q37: 0.1 | S37: 0.1 | U37: 0.1
C38: 4b | E38: Others 2 | G38: 4 | I38: 20 | K38: =$K$37 -> 0.1 | M38: =$M$37 -> 0.1 | O38: =$O$37 -> 0.1 | Q38: =$Q$37 -> 0.1 | S38: =$S$37 -> 0.1 | U38: =$U$37 -> 0.1
C39: 4c | E39: Others 3 | G39: 3 | I39: 20 | K39: =$K$37 -> 0.1 | M39: =$M$37 -> 0.1 | O39: =$O$37 -> 0.1 | Q39: =$Q$37 -> 0.1 | S39: =$S$37 -> 0.1 | U39: =$U$37 -> 0.1
C40: 4d | E40: Others 4 | G40: 2 | I40: 20 | K40: =$K$37 -> 0.1 | M40: =$M$37 -> 0.1 | O40: =$O$37 -> 0.1 | Q40: =$Q$37 -> 0.1 | S40: =$S$37 -> 0.1 | U40: =$U$37 -> 0.1
C41: 4e | E41: Others 5 | G41: 1 | I41: 20 | K41: =$K$37 -> 0.1 | M41: =$M$37 -> 0.1 | O41: =$O$37 -> 0.1 | Q41: =$Q$37 -> 0.1 | S41: =$S$37 -> 0.1 | U41: =$U$37 -> 0.1
C42: Grand Total
C45: 5 | D45: Others
C46: 5a | E46: Others 1 | G46: 5 | I46: 20 | K46: 0.1 | M46: 0.1 | O46: 0.1 | Q46: 0.1 | S46: 0.1 | U46: 0.1
C47: 5b | E47: Others 2 | G47: 4 | I47: 20 | K47: =$K$46 -> 0.1 | M47: =$M$46 -> 0.1 | O47: =$O$46 -> 0.1 | Q47: =$Q$46 -> 0.1 | S47: =$S$46 -> 0.1 | U47: =$U$46 -> 0.1
C48: 5c | E48: Others 3 | G48: 3 | I48: 20 | K48: =$K$46 -> 0.1 | M48: =$M$46 -> 0.1 | O48: =$O$46 -> 0.1 | Q48: =$Q$46 -> 0.1 | S48: =$S$46 -> 0.1 | U48: =$U$46 -> 0.1
C49: 5d | E49: Others 4 | G49: 2 | I49: 20 | K49: =$K$46 -> 0.1 | M49: =$M$46 -> 0.1 | O49: =$O$46 -> 0.1 | Q49: =$Q$46 -> 0.1 | S49: =$S$46 -> 0.1 | U49: =$U$46 -> 0.1
C50: 5e | E50: Others 5 | G50: 1 | I50: 20 | K50: =$K$46 -> 0.1 | M50: =$M$46 -> 0.1 | O50: =$O$46 -> 0.1 | Q50: =$Q$46 -> 0.1 | S50: =$S$46 -> 0.1 | U50: =$U$46 -> 0.1

Sheet A.III CAPEX
B2: S No | C2: Nature of the Expense | D2: Total Amount of the Project | E2: Cost for the Period Ending
E3: Year 1 Ending | G3: Year 2 Ending | H3: Year 3 Ending | I3: Year 4 Ending | J3: Year 5 Ending
E4: 31/03/2025 | F4: Year 1 Total | G4: 31/03/2027 | H4: 31/03/2028 | I4: 31/03/2029 | J4: 31/03/2030
B7: 1 | C7: Office Expenses | D7: =SUM(F7:J7) -> 0 | F7: =SUM(E7:E7) -> 0
C8: Laptop | D8: =SUM(F8:J8) -> 0 | F8: =SUM(E8:E8) -> 0
C9: Mobile | D9: =SUM(F9:J9) -> 0 | F9: =SUM(E9:E9) -> 0
C10: Monitor
C11: Tab
C12: Printer
B14: 2
D15: =SUM(F15:J15) -> 0 | F15: =SUM(E15:E15) -> 0
D16: =SUM(F16:J16) -> 0 | F16: =SUM(E16:E16) -> 0
B18: 3 | D18: 0 | F18: 0
D19: 0
D20: 0
D21: 0
B24: 4
D25: 0 | F25: 0
B27: 5 | D27: 0 | F27: 0
B32: 6 | D32: =SUM(F32:J32) -> 0 | F32: =SUM(E32:E32) -> 0
B35: Total Amount | D35: 510000000 | E35: =SUM(E7:E34) -> 0 | F35: =SUM(F7:F34) -> 0 | G35: =SUM(G7:G34) -> 0 | H35: 430000000 | I35: =SUM(I7:I34) -> 0 | J35: =SUM(J7:J34) -> 0
C41: 40 Cr is Equipment
C42: Civil

Sheet B.I Sales - P1 (2)
L1: =Branch!D4 -> 45961 | P1: =EOMONTH(L1,1) -> 45991 | T1: =EOMONTH(P1,1) -> 46022 | X1: =EOMONTH(T1,1) -> 46053 | AB1: =EOMONTH(X1,1) -> 46081 | AF1: =EOMONTH(AB1,1) -> 46112 | AJ1: =EOMONTH(AF1,1) -> 46142 | AN1: =EOMONTH(AJ1,1) -> 46173 | AR1: =EOMONTH(AN1,1) -> 46203 | AV1: =EOMONTH(AR1,1) -> 46234 | AZ1: =EOMONTH(AV1,1) -> 46265 | BD1: =EOMONTH(AZ1,1) -> 46295 | BH1: =EOMONTH(BD1,1) -> 46326 | BL1: =EOMONTH(BH1,1) -> 46356 | BP1: =EOMONTH(BL1,1) -> 46387 | BT1: =EOMONTH(BP1,1) -> 46418 | BX1: =EOMONTH(BT1,1) -> 46446 | CB1: =EOMONTH(BX1,1) -> 46477 | CF1: =EOMONTH(CB1,1) -> 46507 | CJ1: =EOMONTH(CF1,1) -> 46538 | CN1: =EOMONTH(CJ1,1) -> 46568 | CR1: =EOMONTH(CN1,1) -> 46599 | CV1: =EOMONTH(CR1,1) -> 46630 | CZ1: =EOMONTH(CV1,1) -> 46660 | DD1: =EOMONTH(CZ1,1) -> 46691 | DH1: =EOMONTH(DD1,1) -> 46721 | DL1: =EOMONTH(DH1,1) -> 46752 | DP1: =EOMONTH(DL1,1) -> 46783 | DT1: =EOMONTH(DP1,1) -> 46812 | DX1: =EOMONTH(DT1,1) -> 46843 | EB1: =EOMONTH(DX1,1) -> 46873 | EF1: =EOMONTH(EB1,1) -> 46904 | EJ1: =EOMONTH(EF1,1) -> 46934 | EN1: =EOMONTH(EJ1,1) -> 46965 | ER1: =EOMONTH(EN1,1) -> 46996 | EV1: =EOMONTH(ER1,1) -> 47026 | EZ1: =EOMONTH(EV1,1) -> 47057 | FD1: =EOMONTH(EZ1,1) -> 47087 | FH1: =EOMONTH(FD1,1) -> 47118 | FL1: =EOMONTH(FH1,1) -> 47149 | FP1: =EOMONTH(FL1,1) -> 47177 | FT1: =EOMONTH(FP1,1) -> 47208 | FX1: =EOMONTH(FT1,1) -> 47238 | GB1: =EOMONTH(FX1,1) -> 47269 | GF1: =EOMONTH(GB1,1) -> 47299 | GJ1: =EOMONTH(GF1,1) -> 47330 | GN1: =EOMONTH(GJ1,1) -> 47361 | GR1: =EOMONTH(GN1,1) -> 47391 | GV1: =EOMONTH(GR1,1) -> 47422 | GZ1: =EOMONTH(GV1,1) -> 47452 | HD1: =EOMONTH(GZ1,1) -> 47483 | HH1: =EOMONTH(HD1,1) -> 47514 | HL1: =EOMONTH(HH1,1) -> 47542 | HP1: =EOMONTH(HL1,1) -> 47573 | HT1: =EOMONTH(HP1,1) -> 47603 | HX1: =EOMONTH(HT1,1) -> 47634 | IB1: =EOMONTH(HX1,1) -> 47664 | IF1: =EOMONTH(IB1,1) -> 47695 | IJ1: =EOMONTH(IF1,1) -> 47726 | IN1: =EOMONTH(IJ1,1) -> 47756 | IR1: =EOMONTH(IN1,1) -> 47787 | IV1: =EOMONTH(IR1,1) -> 47817 | IZ1: =EOMONTH(IV1,1) -> 47848 | JD1: =EOMONTH(IZ1,1) -> 47879 | JH1: =EOMONTH(JD1,1) -> 47907 | JL1: =EOMONTH(JH1,1) -> 47938 | JP1: =EOMONTH(JL1,1) -> 47968 | JT1: =EOMONTH(JP1,1) -> 47999 | JX1: =EOMONTH(JT1,1) -> 48029 | KB1: =EOMONTH(JX1,1) -> 48060 | KF1: =EOMONTH(KB1,1) -> 48091
B2: A | C2: Do not enter any data in this sheet | E2: Number of branches | G2: Number of branches | K2: 3 | L2: =Branch!F4 -> 0.15 | O2: =VLOOKUP(O5,Branch!$D$4:$E$74,2,0) -> 3 | P2: =1+(L2*45%) -> 1.0675 | S2: =VLOOKUP(S5,Branch!$D$4:$E$74,2,0) -> 4 | T2: =1+Branch!F6 -> 1.15 | W2: =VLOOKUP(W5,Branch!$D$4:$E$74,2,0) -> 5 | X2: =1+Branch!F7 -> 1.15 | AA2: =VLOOKUP(AA5,Branch!$D$4:$E$74,2,0) -> 8 | AB2: =1+Branch!F8 -> 1.15 | AE2: =VLOOKUP(AE5,Branch!$D$4:$E$74,2,0) -> 10 | AF2: =1+Branch!F9 -> 1.15 | AI2: =VLOOKUP(AI5,Branch!$D$4:$E$74,2,0) -> 10 | AJ2: =1+Branch!F10 -> 1.15 | AM2: =VLOOKUP(AM5,Branch!$D$4:$E$74,2,0) -> 10 | AN2: =1+Branch!F11 -> 1.15 | AQ2: =VLOOKUP(AQ5,Branch!$D$4:$E$74,2,0) -> 10 | AR2: =1+Branch!F12 -> 1.15 | AU2: =VLOOKUP(AU5,Branch!$D$4:$E$74,2,0) -> 10 | AV2: =1+Branch!F13 -> 1.15 | AY2: =VLOOKUP(AY5,Branch!$D$4:$E$74,2,0) -> 10 | AZ2: =1+Branch!F14 -> 1.15 | BC2: =VLOOKUP(BC5,Branch!$D$4:$E$74,2,0) -> 10 | BD2: =1+Branch!F15 -> 1.15 | BG2: =VLOOKUP(BG5,Branch!$D$4:$E$74,2,0) -> 10 | BH2: =1+Branch!F16 -> 1.15 | BK2: =VLOOKUP(BK5,Branch!$D$4:$E$74,2,0) -> 10 | BL2: =1+Branch!F17 -> 1.15 | BO2: =VLOOKUP(BO5,Branch!$D$4:$E$74,2,0) -> 10 | BP2: =1+Branch!F18 -> 1.15 | BS2: =VLOOKUP(BS5,Branch!$D$4:$E$74,2,0) -> 10 | BT2: =1+Branch!F19 -> 1.15 | BW2: =VLOOKUP(BW5,Branch!$D$4:$E$74,2,0) -> 10 | BX2: =1+Branch!F20 -> 1.15 | CA2: =VLOOKUP(CA5,Branch!$D$4:$E$74,2,0) -> 10 | CB2: =1+Branch!F21 -> 1.15 | CE2: =VLOOKUP(CE5,Branch!$D$4:$E$74,2,0) -> 10 | CF2: =1+Branch!F22 -> 1.15 | CI2: =VLOOKUP(CI5,Branch!$D$4:$E$74,2,0) -> 10 | CJ2: =1+Branch!F23 -> 1.15 | CM2: =VLOOKUP(CM5,Branch!$D$4:$E$74,2,0) -> 10 | CN2: =1+Branch!F24 -> 1.15 | CQ2: =VLOOKUP(CQ5,Branch!$D$4:$E$74,2,0) -> 10 | CR2: =1+Branch!F25 -> 1.15 | CU2: =VLOOKUP(CU5,Branch!$D$4:$E$74,2,0) -> 10 | CV2: =1+Branch!F26 -> 1.15 | CY2: =VLOOKUP(CY5,Branch!$D$4:$E$74,2,0) -> 10 | CZ2: =1+Branch!F27 -> 1.15 | DC2: =VLOOKUP(DC5,Branch!$D$4:$E$74,2,0) -> 10 | DD2: =1+Branch!F28 -> 1.15 | DG2: =VLOOKUP(DG5,Branch!$D$4:$E$74,2,0) -> 10 | DH2: =1+Branch!F29 -> 1.15 | DK2: =VLOOKUP(DK5,Branch!$D$4:$E$74,2,0) -> 10 | DL2: =1+Branch!F30 -> 1.15 | DO2: =VLOOKUP(DO5,Branch!$D$4:$E$74,2,0) -> 10 | DP2: =1+Branch!F31 -> 1.15 | DS2: =VLOOKUP(DS5,Branch!$D$4:$E$74,2,0) -> 10 | DT2: =1+Branch!F32 -> 1.15 | DW2: =VLOOKUP(DW5,Branch!$D$4:$E$74,2,0) -> 10 | DX2: =1+Branch!F33 -> 1.15 | EA2: =VLOOKUP(EA5,Branch!$D$4:$E$74,2,0) -> 10 | EB2: =1+Branch!F34 -> 1.15 | EE2: =VLOOKUP(EE5,Branch!$D$4:$E$74,2,0) -> 10 | EF2: =1+Branch!F35 -> 1.15 | EI2: =VLOOKUP(EI5,Branch!$D$4:$E$74,2,0) -> 10 | EJ2: =1+Branch!F36 -> 1.15 | EM2: =VLOOKUP(EM5,Branch!$D$4:$E$74,2,0) -> 10 | EN2: =1+Branch!F37 -> 1.15 | EQ2: =VLOOKUP(EQ5,Branch!$D$4:$E$74,2,0) -> 10 | ER2: =1+Branch!F38 -> 1.15 | EU2: =VLOOKUP(EU5,Branch!$D$4:$E$74,2,0) -> 10 | EV2: =1+Branch!F39 -> 1.15 | EY2: =VLOOKUP(EY5,Branch!$D$4:$E$74,2,0) -> 10 | EZ2: =1+Branch!F40 -> 1.15 | FC2: =VLOOKUP(FC5,Branch!$D$4:$E$74,2,0) -> 10 | FD2: =1+Branch!F41 -> 1.15 | FG2: =VLOOKUP(FG5,Branch!$D$4:$E$74,2,0) -> 10 | FH2: =1+Branch!F42 -> 1.15 | FK2: =VLOOKUP(FK5,Branch!$D$4:$E$74,2,0) -> 10 | FL2: =1+Branch!F43 -> 1.15 | FO2: =VLOOKUP(FO5,Branch!$D$4:$E$74,2,0) -> 10 | FP2: =1+Branch!F44 -> 1.15 | FS2: =VLOOKUP(FS5,Branch!$D$4:$E$74,2,0) -> 10 | FT2: =1+Branch!F45 -> 1.15 | FW2: =VLOOKUP(FW5,Branch!$D$4:$E$74,2,0) -> 10 | FX2: =1+Branch!F46 -> 1.15 | GA2: =VLOOKUP(GA5,Branch!$D$4:$E$74,2,0) -> 10 | GB2: =1+Branch!F47 -> 1.15 | GE2: =VLOOKUP(GE5,Branch!$D$4:$E$74,2,0) -> 10 | GF2: =1+Branch!F48 -> 1.15 | GI2: =VLOOKUP(GI5,Branch!$D$4:$E$74,2,0) -> 10 | GJ2: =1+Branch!F49 -> 1.15 | GM2: =VLOOKUP(GM5,Branch!$D$4:$E$74,2,0) -> 10 | GN2: =1+Branch!F50 -> 1.15 | GQ2: =VLOOKUP(GQ5,Branch!$D$4:$E$74,2,0) -> 10 | GR2: =1+Branch!F51 -> 1.15 | GU2: =VLOOKUP(GU5,Branch!$D$4:$E$74,2,0) -> 10 | GV2: =1+Branch!F52 -> 1.15 | GY2: =VLOOKUP(GY5,Branch!$D$4:$E$74,2,0) -> 10 | GZ2: =1+Branch!F53 -> 1.15 | HC2: =VLOOKUP(HC5,Branch!$D$4:$E$74,2,0) -> 10 | HD2: =1+Branch!F54 -> 1.15 | HG2: =VLOOKUP(HG5,Branch!$D$4:$E$74,2,0) -> 10 | HH2: =1+Branch!F55 -> 1.15 | HK2: =VLOOKUP(HK5,Branch!$D$4:$E$74,2,0) -> 10 | HL2: =1+Branch!F56 -> 1.15 | HO2: =VLOOKUP(HO5,Branch!$D$4:$E$74,2,0) -> 10 | HP2: =1+Branch!F57 -> 1.15 | HS2: =VLOOKUP(HS5,Branch!$D$4:$E$74,2,0) -> 10 | HT2: =1+Branch!F58 -> 1.15 | HW2: =VLOOKUP(HW5,Branch!$D$4:$E$74,2,0) -> 10 | HX2: =1+Branch!F59 -> 1.15 | IA2: =VLOOKUP(IA5,Branch!$D$4:$E$74,2,0) -> 10 | IB2: =1+Branch!F60 -> 1.15 | IE2: =VLOOKUP(IE5,Branch!$D$4:$E$74,2,0) -> 10 | IF2: =1+Branch!F61 -> 1.15 | II2: =VLOOKUP(II5,Branch!$D$4:$E$74,2,0) -> 10 | IJ2: =1+Branch!F62 -> 1.15 | IM2: =VLOOKUP(IM5,Branch!$D$4:$E$74,2,0) -> 10 | IN2: =1+Branch!F63 -> 1.15 | IQ2: =VLOOKUP(IQ5,Branch!$D$4:$E$74,2,0) -> 10 | IR2: =1+Branch!F64 -> 1.15 | IU2: =VLOOKUP(IU5,Branch!$D$4:$E$74,2,0) -> 10 | IV2: =1+Branch!F65 -> 1.15 | IY2: =VLOOKUP(IY5,Branch!$D$4:$E$74,2,0) -> 10 | IZ2: =1+Branch!F66 -> 1.15 | JC2: =VLOOKUP(JC5,Branch!$D$4:$E$74,2,0) -> 10 | JD2: =1+Branch!F67 -> 1.15 | JG2: =VLOOKUP(JG5,Branch!$D$4:$E$74,2,0) -> 10 | JH2: =1+Branch!F68 -> 1.15 | JK2: =VLOOKUP(JK5,Branch!$D$4:$E$74,2,0) -> 10 | JL2: =1+Branch!F69 -> 1.15 | JO2: =VLOOKUP(JO5,Branch!$D$4:$E$74,2,0) -> 10 | JP2: =1+Branch!F70 -> 1.15 | JS2: =VLOOKUP(JS5,Branch!$D$4:$E$74,2,0) -> 10 | JT2: =1+Branch!F71 -> 1.15 | JW2: =VLOOKUP(JW5,Branch!$D$4:$E$74,2,0) -> 10 | JX2: =1+Branch!F72 -> 1.15 | KA2: =VLOOKUP(KA5,Branch!$D$4:$E$74,2,0) -> 10 | KB2: =1+Branch!F73 -> 1.15 | KE2: =VLOOKUP(KE5,Branch!$D$4:$E$74,2,0) -> 10 | KF2: =1+Branch!F74 -> 1.15
