Workbook

Sheet 1. Basics
B2: 1 | C2: Legal Name of the Business | D2: CYNCURA PRIVATE LIMITED
B4: 2 | C4: Trade Name of the Business | D4: CYNCURA PRIVATE LIMITED
B6: 3 | C6: Registered Office Address | D6: 6-1-19 and 6-1-19/A, old no 108/3, Flat no 206, Musheerabad (Delivery), Hyderabad, Hyderabad- 500020, Telangana
B8: 4 | C8: Official Email Id | D8: Karimsavenue@gmail.com
B10: 5 | C10: Official Contact Number
B12: 6 | C12: Details of the Promoter
B14: 6.a | C14: Total number of Promoters | D14: 4
B16: 7 | C16: Tentative Start Date of the project Phase 1 | D16: 46112 | E16: DD/MM/YYYY
B18: 8 | C18: Company Description
B20: 9 | C20: Link to Company Pitch Deck
B22: 10 | C22: Burning Desire of the company
B24: 11 | C24: Tentative Start Date of the project Phase 2

Sheet A. Data Needed
C2: Major heads of the data needed for the business plan
D3: Hyperlink to open
B4: I | C4: We need to clearly define the Revenue Streams | D4: Nature of services. click here for the link to enter the revenue streams
B7: II | C7: Sales price per revenue streams | D7: Click
B9: III | C9: Costing headers | D9: =A.IIOPEX!C2 -> Opex, Click on the link to refer to OPEX
B11: IIV | C11: Capex Information | D11: Capex Click on the link to refer to Capex
B13: V | C13: Other Information

Sheet A.I Revenue Streams - P1
C2: Revenue Streams
C3: This Sheet assists us in getting the data related to Sales
C5: PHASE - 1 | E5: ='1. Basics'!D16 -> 46112
K6: 2026-27 | M6: 2027-28 | O6: 2028-29 | Q6: 2029-30 | S6: 2030-31 | U6: 2031-32
D8: Major Header | E8: Minor Header | G8: Number of Products sold per month | I8: Sale Price of each product | K8: Monthly Growth Rate in Y2 | M8: Yearly Growth Rate from Y2 to Y3 | O8: Yearly Growth Rate from Y3 to Y4 | Q8: Yearly Growth Rate from Y4 to Y5 | S8: Yearly Growth Rate from Y5 to Y6 | U8: Yearly Growth Rate from Y6 to Y7
C9: 1 | D9: Doctor Consultations
C10: 1a | E10: Platform Access Fees | G10: =2000*50%*28 -> 28000 | I10: 30 | K10: 0.01 | M10: 0.82 | O10: 0.7 | Q10: 0.55 | S10: 0.45 | U10: 0.4
C11: 1b | K11: =$K$10 -> 0.01 | M11: =$M$10 -> 0.82 | O11: =$O$10 -> 0.7 | Q11: =$Q$10 -> 0.55 | S11: =$S$10 -> 0.45 | U11: =$U$10 -> 0.4
C12: 1c | K12: =$K$10 -> 0.01 | M12: =$M$10 -> 0.82 | O12: =$O$10 -> 0.7 | Q12: =$Q$10 -> 0.55 | S12: =$S$10 -> 0.45 | U12: =$U$10 -> 0.4
C13: 1d | K13: =$K$10 -> 0.01 | M13: =$M$10 -> 0.82 | O13: =$O$10 -> 0.7 | Q13: =$Q$10 -> 0.55 | S13: =$S$10 -> 0.45 | U13: =$U$10 -> 0.4
C14: 1e | K14: =$K$10 -> 0.01 | M14: =$M$10 -> 0.82 | O14: =$O$10 -> 0.7 | Q14: =$Q$10 -> 0.55 | S14: =$S$10 -> 0.45 | U14: =$U$10 -> 0.4
C15: Grand Total
C18: 2 | D18: Advertisement
C19: 2a | E19: Advertisement | K19: 0 | M19: 0 | O19: 0 | Q19: 0 | S19: 0 | U19: 0
C20: 2b | K20: =$K$19 -> 0 | M20: =$M$19 -> 0 | O20: =$O$19 -> 0 | Q20: =$Q$19 -> 0 | S20: =$S$19 -> 0 | U20: =$U$19 -> 0
C21: 2c | K21: =$K$19 -> 0 | M21: =$M$19 -> 0 | O21: =$O$19 -> 0 | Q21: =$Q$19 -> 0 | S21: =$S$19 -> 0 | U21: =$U$19 -> 0
C22: 2d | K22: =$K$19 -> 0 | M22: =$M$19 -> 0 | O22: =$O$19 -> 0 | Q22: =$Q$19 -> 0 | S22: =$S$19 -> 0 | U22: =$U$19 -> 0
C23: 2e | K23: =$K$19 -> 0 | M23: =$M$19 -> 0 | O23: =$O$19 -> 0 | Q23: =$Q$19 -> 0 | S23: =$S$19 -> 0 | U23: =$U$19 -> 0
C24: Grand Total
C27: 3
C28: 3a | K28: 0 | M28: 0 | O28: 1.23 | Q28: 1.23 | S28: 0 | U28: 0
C29: 3b | K29: =$K$28 -> 0 | M29: =$M$28 -> 0 | O29: =$O$28 -> 1.23 | Q29: =$Q$28 -> 1.23 | S29: =$S$28 -> 0 | U29: =$U$28 -> 0
C30: 3c | K30: =$K$28 -> 0 | M30: =$M$28 -> 0 | O30: =$O$28 -> 1.23 | Q30: =$Q$28 -> 1.23 | S30: =$S$28 -> 0 | U30: =$U$28 -> 0
C31: 3d | K31: =$K$28 -> 0 | M31: =$M$28 -> 0 | O31: =$O$28 -> 1.23 | Q31: =$Q$28 -> 1.23 | S31: =$S$28 -> 0 | U31: =$U$28 -> 0
C32: 3e | K32: =$K$28 -> 0 | M32: =$M$28 -> 0 | O32: =$O$28 -> 1.23 | Q32: =$Q$28 -> 1.23 | S32: =$S$28 -> 0 | U32: =$U$28 -> 0
C33: Grand Total
C36: 4
C37: 4a | K37: 0 | M37: 0 | O37: 1.23 | Q37: 1.23 | S37: 0 | U37: 0
C38: 4b | K38: =$K$37 -> 0 | M38: =$M$37 -> 0 | O38: =$O$37 -> 1.23 | Q38: =$Q$37 -> 1.23 | S38: =$S$37 -> 0 | U38: =$U$37 -> 0
C39: 4c | K39: =$K$37 -> 0 | M39: =$M$37 -> 0 | O39: =$O$37 -> 1.23 | Q39: =$Q$37 -> 1.23 | S39: =$S$37 -> 0 | U39: =$U$37 -> 0
C40: 4d | K40: =$K$37 -> 0 | M40: =$M$37 -> 0 | O40: =$O$37 -> 1.23 | Q40: =$Q$37 -> 1.23 | S40: =$S$37 -> 0 | U40: =$U$37 -> 0
C41: 4e | K41: =$K$37 -> 0 | M41: =$M$37 -> 0 | O41: =$O$37 -> 1.23 | Q41: =$Q$37 -> 1.23 | S41: =$S$37 -> 0 | U41: =$U$37 -> 0
C42: Grand Total
C45: 5
C46: 5a | K46: 0 | M46: 0 | O46: 1.23 | Q46: 1.23 | S46: 0 | U46: 0
C47: 5b | K47: =$K$46 -> 0 | M47: =$M$46 -> 0 | O47: =$O$46 -> 1.23 | Q47: =$Q$46 -> 1.23 | S47: =$S$46 -> 0 | U47: =$U$46 -> 0
C48: 5c | K48: =$K$46 -> 0 | M48: =$M$46 -> 0 | O48: =$O$46 -> 1.23 | Q48: =$Q$46 -> 1.23 | S48: =$S$46 -> 0 | U48: =$U$46 -> 0
C49: 5d | K49: =$K$46 -> 0 | M49: =$M$46 -> 0 | O49: =$O$46 -> 1.23 | Q49: =$Q$46 -> 1.23 | S49: =$S$46 -> 0 | U49: =$U$46 -> 0
C50: 5e | K50: =$K$46 -> 0 | M50: =$M$46 -> 0 | O50: =$O$46 -> 1.23 | Q50: =$Q$46 -> 1.23 | S50: =$S$46 -> 0 | U50: =$U$46 -> 0
C51: Grand Total

Sheet A.I Revenue Streams - P2
C2: Revenue Streams
C3: This Sheet assists us in getting the data related to Sales
C5: PHASE - 2 | E5: ='1. Basics'!D24 -> 0
D8: Major Header | E8: Minor Header | G8: Number of Products sold per Day | I8: Sale Price of each product | K8: Monthly Growth Rate in Y1 | M8: Yearly Growth Rate from Y1 to Y2 | O8: Yearly Growth Rate from Y2 to Y3 | Q8: Yearly Growth Rate from Y3 to Y4 | S8: Yearly Growth Rate from Y4 to Y5 | U8: Yearly Growth Rate from Y5 to Y6
C9: 1 | D9: Cakes
C10: 1a | E10: Cup Cakes | G10: 5 | I10: 20 | K10: 0.1 | M10: 0.1 | O10: 0.1 | Q10: 0.1 | S10: 0.1 | U10: 0.1
C11: 1b | E11: Customised Cakes | G11: 4 | I11: 20 | K11: =$K$10 -> 0.1 | M11: =$M$10 -> 0.1 | O11: =$O$10 -> 0.1 | Q11: =$Q$10 -> 0.1 | S11: =$S$10 -> 0.1 | U11: =$U$10 -> 0.1
C12: 1c | E12: Standard Cake | G12: 3 | I12: 20 | K12: =$K$10 -> 0.1 | M12: =$M$10 -> 0.1 | O12: =$O$10 -> 0.1 | Q12: =$Q$10 -> 0.1 | S12: =$S$10 -> 0.1 | U12: =$U$10 -> 0.1
C13: 1d | E13: Cake Slices | G13: 2 | I13: 20 | K13: =$K$10 -> 0.1 | M13: =$M$10 -> 0.1 | O13: =$O$10 -> 0.1 | Q13: =$Q$10 -> 0.1 | S13: =$S$10 -> 0.1 | U13: =$U$10 -> 0.1
C14: 1e | E14: 0 | G14: 1 | I14: 20 | K14: =$K$10 -> 0.1 | M14: =$M$10 -> 0.1 | O14: =$O$10 -> 0.1 | Q14: =$Q$10 -> 0.1 | S14: =$S$10 -> 0.1 | U14: =$U$10 -> 0.1
C15: Grand Total
C18: 2 | D18: Confectionary
C19: 2a | E19: Burgers | G19: 5 | I19: 20 | K19: 0.1 | M19: 0.1 | O19: 0.1 | Q19: 0.1 | S19: 0.1 | U19: 0.1
C20: 2b | E20: Pizza | G20: 4 | I20: 20 | K20: =$K$19 -> 0.1 | M20: =$M$19 -> 0.1 | O20: =$O$19 -> 0.1 | Q20: =$Q$19 -> 0.1 | S20: =$S$19 -> 0.1 | U20: =$U$19 -> 0.1
C21: 2c | E21: Puffs | G21: 3 | I21: 20 | K21: =$K$19 -> 0.1 | M21: =$M$19 -> 0.1 | O21: =$O$19 -> 0.1 | Q21: =$Q$19 -> 0.1 | S21: =$S$19 -> 0.1 | U21: =$U$19 -> 0.1
C22: 2d | E22: Other 1 | G22: 2 | I22: 20 | K22: =$K$19 -> 0.1 | M22: =$M$19 -> 0.1 | O22: =$O$19 -> 0.1 | Q22: =$Q$19 -> 0.1 | S22: =$S$19 -> 0.1 | U22: =$U$19 -> 0.1
C23: 2e | E23: 0 | G23: 1 | I23: 20 | K23: =$K$19 -> 0.1 | M23: =$M$19 -> 0.1 | O23: =$O$19 -> 0.1 | Q23: =$Q$19 -> 0.1 | S23: =$S$19 -> 0.1 | U23: =$U$19 -> 0.1
C24: Grand Total
C27: 3 | D27: Accessorries
C28: 3a | E28: Poppers | G28: 5 | I28: 20 | K28: 0.1 | M28: 0.1 | O28: 0.1 | Q28: 0.1 | S28: 0.1 | U28: 0.1
C29: 3b | E29: Builders | G29: 4 | I29: 20 | K29: =$K$28 -> 0.1 | M29: =$M$28 -> 0.1 | O29: =$O$28 -> 0.1 | Q29: =$Q$28 -> 0.1 | S29: =$S$28 -> 0.1 | U29: =$U$28 -> 0.1
C30: 3c | E30: Blasters | G30: 3 | I30: 20 | K30: =$K$28 -> 0.1 | M30: =$M$28 -> 0.1 | O30: =$O$28 -> 0.1 | Q30: =$Q$28 -> 0.1 | S30: =$S$28 -> 0.1 | U30: =$U$28 -> 0.1
C31: 3d | E31: Decor | G31: 2 | I31: 20 | K31: =$K$28 -> 0.1 | M31: =$M$28 -> 0.1 | O31: =$O$28 -> 0.1 | Q31: =$Q$28 -> 0.1 | S31: =$S$28 -> 0.1 | U31: =$U$28 -> 0.1
C32: 3e | E32: Others | G32: 1 | I32: 20 | K32: =$K$28 -> 0.1 | M32: =$M$28 -> 0.1 | O32: =$O$28 -> 0.1 | Q32: =$Q$28 -> 0.1 | S32: =$S$28 -> 0.1 | U32: =$U$28 -> 0.1
C33: Grand Total
C36: 4 | D36: Others
C37: 4a | E37: Others 1 | G37: 5 | I37: 20 | K37: 0.1 | M37: 0.1 | O37: 0.1 | Q37: 0.1 | S37: 0.1 | U37: 0.1
C38: 4b | E38: Others 2 | G38: 4 | I38: 20 | K38: =$K$37 -> 0.1 | M38: =$M$37 -> 0.1 | O38: =$O$37 -> 0.1 | Q38: =$Q$37 -> 0.1 | S38: =$S$37 -> 0.1 | U38: =$U$37 -> 0.1
C39: 4c | E39: Others 3 | G39: 3 | I39: 20 | K39: =$K$37 -> 0.1 | M39: =$M$37 -> 0.1 | O39: =$O$37 -> 0.1 | Q39: =$Q$37 -> 0.1 | S39: =$S$37 -> 0.1 | U39: =$U$37 -> 0.1
C40: 4d | E40: Others 4 | G40: 2 | I40: 20 | K40: =$K$37 -> 0.1 | M40: =$M$37 -> 0.1 | O40: =$O$37 -> 0.1 | Q40: =$Q$37 -> 0.1 | S40: =$S$37 -> 0.1 | U40: =$U$37 -> 0.1
C41: 4e | E41: Others 5 | G41: 1 | I41: 20 | K41: =$K$37 -> 0.1 | M41: =$M$37 -> 0.1 | O41: =$O$37 -> 0.1 | Q41: =$Q$37 -> 0.1 | S41: =$S$37 -> 0.1 | U41: =$U$37 -> 0.1
C42: Grand Total
C45: 5 | D45: Others
C46: 5a | E46: Others 1 | G46: 5 | I46: 20 | K46: 0.1 | M46: 0.1 | O46: 0.1 | Q46: 0.1 | S46: 0.1 | U46: 0.1
C47: 5b | E47: Others 2 | G47: 4 | I47: 20 | K47: =$K$46 -> 0.1 | M47: =$M$46 -> 0.1 | O47: =$O$46 -> 0.1 | Q47: =$Q$46 -> 0.1 | S47: =$S$46 -> 0.1 | U47: =$U$46 -> 0.1
C48: 5c | E48: Others 3 | G48: 3 | I48: 20 | K48: =$K$46 -> 0.1 | M48: =$M$46 -> 0.1 | O48: =$O$46 -> 0.1 | Q48: =$Q$46 -> 0.1 | S48: =$S$46 -> 0.1 | U48: =$U$46 -> 0.1
C49: 5d | E49: Others 4 | G49: 2 | I49: 20 | K49: =$K$46 -> 0.1 | M49: =$M$46 -> 0.1 | O49: =$O$46 -> 0.1 | Q49: =$Q$46 -> 0.1 | S49: =$S$46 -> 0.1 | U49: =$U$46 -> 0.1
C50: 5e | E50: Others 5 | G50: 1 | I50: 20 | K50: =$K$46 -> 0.1 | M50: =$M$46 -> 0.1 | O50: =$O$46 -> 0.1 | Q50: =$Q$46 -> 0.1 | S50: =$S$46 -> 0.1 | U50: =$U$46 -> 0.1

Sheet A.IIOPEX
C2: Opex, Click on the link to refer to OPEX
C4: Write down all the major and nimor headers for the costing and list them here
C5: Beside the header you will be able to write the quantity and the price
K6: 2025-26 | M6: 2026-27 | O6: 2027-28 | Q6: 2028-29 | S6: 2029-30 | U6: 2030-31
D8: Major Header | E8: Sub Services | G8: Monthly | I8: Cost per month | K8: Monthly Growth Rate in Y1 | M8: Yearly Growth Rate from Y1 to Y2 | O8: Yearly Growth Rate from Y2 to Y3 | Q8: Yearly Growth Rate from Y3 to Y4 | S8: Yearly Growth Rate from Y4 to Y5 | U8: Yearly Growth Rate from Y5 to Y6
C9: 1 | D9: Technology & Product Development
C10: 1a | E10: App Development | G10: 2 | I10: =1000000/12 -> 83333.333 | K10: -0.2 | M10: 0.35 | O10: 2.5 | Q10: 3.8 | S10: 0.4 | U10: 0.35
C11: 1b | E11: App maintenance | G11: 3 | K11: =$K$10 -> -0.2 | M11: =$M$10 -> 0.35 | O11: =$O$10 -> 2.5 | Q11: =$Q$10 -> 3.8 | S11: =$S$10 -> 0.4 | U11: =$U$10 -> 0.35
C12: 1c | G12: 2 | K12: =$K$10 -> -0.2 | M12: =$M$10 -> 0.35 | O12: =$O$10 -> 2.5 | Q12: =$Q$10 -> 3.8 | S12: =$S$10 -> 0.4 | U12: =$U$10 -> 0.35
C13: 1d | G13: 1 | K13: =$K$10 -> -0.2 | M13: =$M$10 -> 0.35 | O13: =$O$10 -> 2.5 | Q13: =$Q$10 -> 3.8 | S13: =$S$10 -> 0.4 | U13: =$U$10 -> 0.35
C14: 1e | G14: 2 | K14: =$K$10 -> -0.2 | M14: =$M$10 -> 0.35 | O14: =$O$10 -> 2.5 | Q14: =$Q$10 -> 3.8 | S14: =$S$10 -> 0.4 | U14: =$U$10 -> 0.35
C15: 1f | G15: 5 | K15: =$K$10 -> -0.2 | M15: =$M$10 -> 0.35 | O15: =$O$10 -> 2.5 | Q15: =$Q$10 -> 3.8 | S15: =$S$10 -> 0.4 | U15: =$U$10 -> 0.35
C16: 1g | K16: =$K$10 -> -0.2 | M16: =$M$10 -> 0.35 | O16: =$O$10 -> 2.5 | Q16: =$Q$10 -> 3.8 | S16: =$S$10 -> 0.4 | U16: =$U$10 -> 0.35
C17: Grand Total
C20: 2 | D20: Legal, Compliance & Professional Charges
C21: 2a | E21: Professional Charges | G21: 1 | I21: 50000 | K21: -0.08 | M21: 0.02 | O21: 0.15 | Q21: 0.4 | S21: 0.15 | U21: 0.18
C22: 2b | G22: 2 | K22: =$K$21 -> -0.08 | M22: =$M$21 -> 0.02 | O22: =$O$21 -> 0.15 | Q22: =$Q$21 -> 0.4 | S22: =$S$21 -> 0.15 | U22: =$U$21 -> 0.18
C23: 2c | G23: 2 | K23: =$K$21 -> -0.08 | M23: =$M$21 -> 0.02 | O23: =$O$21 -> 0.15 | Q23: =$Q$21 -> 0.4 | S23: =$S$21 -> 0.15 | U23: =$U$21 -> 0.18
C24: 2d | G24: 1 | K24: =$K$21 -> -0.08 | M24: =$M$21 -> 0.02 | O24: =$O$21 -> 0.15 | Q24: =$Q$21 -> 0.4 | S24: =$S$21 -> 0.15 | U24: =$U$21 -> 0.18
C25: 2e | K25: =$K$21 -> -0.08 | M25: =$M$21 -> 0.02 | O25: =$O$21 -> 0.15 | Q25: =$Q$21 -> 0.4 | S25: =$S$21 -> 0.15 | U25: =$U$21 -> 0.18
C26: 2f | K26: =$K$21 -> -0.08 | M26: =$M$21 -> 0.02 | O26: =$O$21 -> 0.15 | Q26: =$Q$21 -> 0.4 | S26: =$S$21 -> 0.15 | U26: =$U$21 -> 0.18
C27: 2g | K27: =$K$21 -> -0.08 | M27: =$M$21 -> 0.02 | O27: =$O$21 -> 0.15 | Q27: =$Q$21 -> 0.4 | S27: =$S$21 -> 0.15 | U27: =$U$21 -> 0.18
C28: Grand Total
C31: 3 | D31: Utilities
C32: 3a | E32: Office Maintenance | G32: 1
C33: 3b | E33: Rent | G33: 1 | K33: =$K$32 -> -0.08 | M33: =$M$32 -> 0.05 | O33: =$O$32 -> 0.35 | Q33: =$Q$32 -> 0.35 | S33: =$S$32 -> 0.3 | U33: =$U$32 -> 0.3
C34: 3c | E34: Power/ Electricity | K34: =$K$32 -> -0.08 | M34: =$M$32 -> 0.05 | O34: =$O$32 -> 0.35 | Q34: =$Q$32 -> 0.35 | S34: =$S$32 -> 0.3 | U34: =$U$32 -> 0.3
C35: 3d | E35: Miscellaneous | G35: 1 | I35: =1500000/12 -> 125000 | K35: =$K$32 -> -0.08 | M35: =$M$32 -> 0.05 | O35: =$O$32 -> 0.35 | Q35: =$Q$32 -> 0.35 | S35: =$S$32 -> 0.3 | U35: =$U$32 -> 0.3
C36: 3e | K36: =$K$32 -> -0.08 | M36: =$M$32 -> 0.05 | O36: =$O$32 -> 0.35 | Q36: =$Q$32 -> 0.35 | S36: =$S$32 -> 0.3 | U36: =$U$32 -> 0.3
C37: 3f | K37: =$K$32 -> -0.08 | M37: =$M$32 -> 0.05 | O37: =$O$32 -> 0.35 | Q37: =$Q$32 -> 0.35 | S37: =$S$32 -> 0.3 | U37: =$U$32 -> 0.3
C38: 3g | G38: 5 | K38: =$K$32 -> -0.08 | M38: =$M$32 -> 0.05 | O38: =$O$32 -> 0.35 | Q38: =$Q$32 -> 0.35 | S38: =$S$32 -> 0.3 | U38: =$U$32 -> 0.3
C39: 3h | G39: 5 | K39: =$K$32 -> -0.08 | M39: =$M$32 -> 0.05 | O39: =$O$32 -> 0.35 | Q39: =$Q$32 -> 0.35 | S39: =$S$32 -> 0.3 | U39: =$U$32 -> 0.3
C40: 3i | K40: =$K$32 -> -0.08 | M40: =$M$32 -> 0.05 | O40: =$O$32 -> 0.35 | Q40: =$Q$32 -> 0.35 | S40: =$S$32 -> 0.3 | U40: =$U$32 -> 0.3
C41: Grand Total
C44: 4 | D44: Support Team
C45: 4a | E45: Salaries – Tech & Ops | I45: 400000 | K45: -0.5 | M45: 0.15 | O45: 0.1 | Q45: 0.9 | S45: 0.35 | U45: 0.6
C46: 4b | E46: Customer Support Team | I46: 120000 | K46: =$K$45 -> -0.5 | M46: =$M$45 -> 0.15 | O46: =$O$45 -> 0.1 | Q46: =$Q$45 -> 0.9 | S46: =$S$45 -> 0.35 | U46: =$U$45 -> 0.6
C47: 4c | E47: Field Agents | I47: 120000 | K47: =$K$45 -> -0.5 | M47: =$M$45 -> 0.15 | O47: =$O$45 -> 0.1 | Q47: =$Q$45 -> 0.9 | S47: =$S$45 -> 0.35 | U47: =$U$45 -> 0.6
C48: 4d | K48: =$K$45 -> -0.5 | M48: =$M$45 -> 0.15 | O48: =$O$45 -> 0.1 | Q48: =$Q$45 -> 0.9 | S48: =$S$45 -> 0.35 | U48: =$U$45 -> 0.6
C49: 4e | K49: =$K$45 -> -0.5 | M49: =$M$45 -> 0.15 | O49: =$O$45 -> 0.1 | Q49: =$Q$45 -> 0.9 | S49: =$S$45 -> 0.35 | U49: =$U$45 -> 0.6
...

Sheet A.III CAPEX
B2: S No | C2: Nature of the Expense | D2: Total Amount of the Project | E2: Cost for the Period Ending
E3: Year 1 Ending | G3: Year 2 Ending | H3: Year 3 Ending | I3: Year 4 Ending | J3: Year 5 Ending
E4: 31/03/2025 | F4: Year 1 Total | G4: 31/03/2027 | H4: 31/03/2028 | I4: 31/03/2029 | J4: 31/03/2030
B7: 1 | C7: Office Expenses | D7: =SUM(F7:J7) -> 0 | F7: =SUM(E7:E7) -> 0
C8: Laptop | D8: =SUM(F8:J8) -> 0 | F8: =SUM(E8:E8) -> 0
C9: Mobile | D9: =SUM(F9:J9) -> 0 | F9: =SUM(E9:E9) -> 0
C10: Monitor
C11: Tab
C12: Printer
B14: 2
D15: =SUM(F15:J15) -> 0 | F15: =SUM(E15:E15) -> 0
D16: =SUM(F16:J16) -> 0 | F16: =SUM(E16:E16) -> 0
B18: 3 | D18: 0 | F18: 0
D19: 0
D20: 0
D21: 0
B24: 4
D25: 0 | F25: 0
B27: 5 | D27: 0 | F27: 0
B32: 6 | D32: =SUM(F32:J32) -> 0 | F32: =SUM(E32:E32) -> 0
B35: Total Amount | D35: 510000000 | E35: =SUM(E7:E34) -> 0 | F35: =SUM(F7:F34) -> 0 | G35: =SUM(G7:G34) -> 0 | H35: 430000000 | I35: =SUM(I7:I34) -> 0 | J35: =SUM(J7:J34) -> 0
C41: 40 Cr is Equipment
C42: Civil

Sheet B.I Sales - P1
B2: A | C2: Do not enter any data in this sheet
F3: =H3 -> 2026-27 | H3: =IF(MONTH(F5)<=3,TEXT(F5,"yyyy")-1 & "-" & TEXT(F5,"yy"),IF(MONTH(F5)>3,TEXT(F5,"yyyy") & "-" & TEXT(F5,"yy")+1)) -> 2026-27 | J3: =L3 -> 2026-27 | L3: =IF(MONTH(J5)<=3,TEXT(J5,"yyyy")-1 & "-" & TEXT(J5,"yy"),IF(MONTH(J5)>3,TEXT(J5,"yyyy") & "-" & TEXT(J5,"yy")+1)) -> 2026-27 | N3: =P3 -> 2026-27 | P3: =IF(MONTH(N5)<=3,TEXT(N5,"yyyy")-1 & "-" & TEXT(N5,"yy"),IF(MONTH(N5)>3,TEXT(N5,"yyyy") & "-" & TEXT(N5,"yy")+1)) -> 2026-27 | R3: =T3 -> 2026-27 | T3: =IF(MONTH(R5)<=3,TEXT(R5,"yyyy")-1 & "-" & TEXT(R5,"yy"),IF(MONTH(R5)>3,TEXT(R5,"yyyy") & "-" & TEXT(R5,"yy")+1)) -> 2026-27 | V3: =X3 -> 2026-27 | X3: =IF(MONTH(V5)<=3,TEXT(V5,"yyyy")-1 & "-" & TEXT(V5,"yy"),IF(MONTH(V5)>3,TEXT(V5,"yyyy") & "-" & TEXT(V5,"yy")+1)) -> 2026-27 | Z3: =AB3 -> 2026-27 | AB3: =IF(MONTH(Z5)<=3,TEXT(Z5,"yyyy")-1 & "-" & TEXT(Z5,"yy"),IF(MONTH(Z5)>3,TEXT(Z5,"yyyy") & "-" & TEXT(Z5,"yy")+1)) -> 2026-27 | AD3: =AF3 -> 2026-27 | AF3: =IF(MONTH(AD5)<=3,TEXT(AD5,"yyyy")-1 & "-" & TEXT(AD5,"yy"),IF(MONTH(AD5)>3,TEXT(AD5,"yyyy") & "-" & TEXT(AD5,"yy")+1)) -> 2026-27 | AH3: =AJ3 -> 2026-27 | AJ3: =IF(MONTH(AH5)<=3,TEXT(AH5,"yyyy")-1 & "-" & TEXT(AH5,"yy"),IF(MONTH(AH5)>3,TEXT(AH5,"yyyy") & "-" & TEXT(AH5,"yy")+1)) -> 2026-27 | AL3: =AN3 -> 2026-27 | AN3: =IF(MONTH(AL5)<=3,TEXT(AL5,"yyyy")-1 & "-" & TEXT(AL5,"yy"),IF(MONTH(AL5)>3,TEXT(AL5,"yyyy") & "-" & TEXT(AL5,"yy")+1)) -> 2026-27 | AP3: =AR3 -> 2026-27 | AR3: =IF(MONTH(AP5)<=3,TEXT(AP5,"yyyy")-1 & "-" & TEXT(AP5,"yy"),IF(MONTH(AP5)>3,TEXT(AP5,"yyyy") & "-" & TEXT(AP5,"yy")+1)) -> 2026-27 | AT3: =AV3 -> 2026-27 | AV3: =IF(MONTH(AT5)<=3,TEXT(AT5,"yyyy")-1 & "-" & TEXT(AT5,"yy"),IF(MONTH(AT5)>3,TEXT(AT5,"yyyy") & "-" & TEXT(AT5,"yy")+1)) -> 2026-27 | AX3: =AZ3 -> 2026-27 | AZ3: =IF(MONTH(AX5)<=3,TEXT(AX5,"yyyy")-1 & "-" & TEXT(AX5,"yy"),IF(MONTH(AX5)>3,TEXT(AX5,"yyyy") & "-" & TEXT(AX5,"yy")+1)) -> 2026-27 | BB3: =BD3 -> 2027-28 | BD3: =IF(MONTH(BB5)<=3,TEXT(BB5,"yyyy")-1 & "-" & TEXT(BB5,"yy"),IF(MONTH(BB5)>3,TEXT(BB5,"yyyy") & "-" & TEXT(BB5,"yy")+1)) -> 2027-28 | BF3: =BH3 -> 2027-28 | BH3: =IF(MONTH(BF5)<=3,TEXT(BF5,"yyyy")-1 & "-" & TEXT(BF5,"yy"),IF(MONTH(BF5)>3,TEXT(BF5,"yyyy") & "-" & TEXT(BF5,"yy")+1)) -> 2027-28 | BJ3: =BL3 -> 2027-28 | BL3: =IF(MONTH(BJ5)<=3,TEXT(BJ5,"yyyy")-1 & "-" & TEXT(BJ5,"yy"),IF(MONTH(BJ5)>3,TEXT(BJ5,"yyyy") & "-" & TEXT(BJ5,"yy")+1)) -> 2027-28 | BN3: =BP3 -> 2027-28 | BP3: =IF(MONTH(BN5)<=3,TEXT(BN5,"yyyy")-1 & "-" & TEXT(BN5,"yy"),IF(MONTH(BN5)>3,TEXT(BN5,"yyyy") & "-" & TEXT(BN5,"yy")+1)) -> 2027-28 | BR3: =BT3 -> 2027-28 | BT3: =IF(MONTH(BR5)<=3,TEXT(BR5,"yyyy")-1 & "-" & TEXT(BR5,"yy"),IF(MONTH(BR5)>3,TEXT(BR5,"yyyy") & "-" & TEXT(BR5,"yy")+1)) -> 2027-28 | BV3: =BX3 -> 2027-28 | BX3: =IF(MONTH(BV5)<=3,TEXT(BV5,"yyyy")-1 & "-" & TEXT(BV5,"yy"),IF(MONTH(BV5)>3,TEXT(BV5,"yyyy") & "-" & TEXT(BV5,"yy")+1)) -> 2027-28 | BZ3: =CB3 -> 2027-28 | CB3: =IF(MONTH(BZ5)<=3,TEXT(BZ5,"yyyy")-1 & "-" & TEXT(BZ5,"yy"),IF(MONTH(BZ5)>3,TEXT(BZ5,"yyyy") & "-" & TEXT(BZ5,"yy")+1)) -> 2027-28 | CD3: =CF3 -> 2027-28 | CF3: =IF(MONTH(CD5)<=3,TEXT(CD5,"yyyy")-1 & "-" & TEXT(CD5,"yy"),IF(MONTH(CD5)>3,TEXT(CD5,"yyyy") & "-" & TEXT(CD5,"yy")+1)) -> 2027-28 | CH3: =CJ3 -> 2027-28 | CJ3: =IF(MONTH(CH5)<=3,TEXT(CH5,"yyyy")-1 & "-" & TEXT(CH5,"yy"),IF(MONTH(CH5)>3,TEXT(CH5,"yyyy") & "-" & TEXT(CH5,"yy")+1)) -> 2027-28 | CL3: =CN3 -> 2027-28 | CN3: =IF(MONTH(CL5)<=3,TEXT(CL5,"yyyy")-1 & "-" & TEXT(CL5,"yy"),IF(MONTH(CL5)>3,TEXT(CL5,"yyyy") & "-" & TEXT(CL5,"yy")+1)) -> 2027-28 | CP3: =CR3 -> 2027-28 | CR3: =IF(MONTH(CP5)<=3,TEXT(CP5,"yyyy")-1 & "-" & TEXT(CP5,"yy"),IF(MONTH(CP5)>3,TEXT(CP5,"yyyy") & "-" & TEXT(CP5,"yy")+1)) -> 2027-28 | CT3: =CV3 -> 2027-28 | CV3: =IF(MONTH(CT5)<=3,TEXT(CT5,"yyyy")-1 & "-" & TEXT(CT5,"yy"),IF(MONTH(CT5)>3,TEXT(CT5,"yyyy") & "-" & TEXT(CT5,"yy")+1)) -> 2027-28 | CX3: =CZ3 -> 2028-29 | CZ3: =IF(MONTH(CX5)<=3,TEXT(CX5,"yyyy")-1 & "-" & TEXT(CX5,"yy"),IF(MONTH(CX5)>3,TEXT(CX5,"yyyy") & "-" & TEXT(CX5,"yy")+1)) -> 2028-29 | DB3: =DD3 -> 2028-29 | DD3: =IF(MONTH(DB5)<=3,TEXT(DB5,"yyyy")-1 & "-" & TEXT(DB5,"yy"),IF(MONTH(DB5)>3,TEXT(DB5,"yyyy") & "-" & TEXT(DB5,"yy")+1)) -> 2028-29 | DF3: =DH3 -> 2028-29 | DH3: =IF(MONTH(DF5)<=3,TEXT(DF5,"yyyy")-1 & "-" & TEXT(DF5,"yy"),IF(MONTH(DF5)>3,TEXT(DF5,"yyyy") & "-" & TEXT(DF5,"yy")+1)) -> 2028-29 | DJ3: =DL3 -> 2028-29 | DL3: =IF(MONTH(DJ5)<=3,TEXT(DJ5,"yyyy")-1 & "-" & TEXT(DJ5,"yy"),IF(MONTH(DJ5)>3,TEXT(DJ5,"yyyy") & "-" & TEXT(DJ5,"yy")+1)) -> 2028-29 | DN3: =DP3 -> 2028-29 | DP3: =IF(MONTH(DN5)<=3,TEXT(DN5,"yyyy")-1 & "-" & TEXT(DN5,"yy"),IF(MONTH(DN5)>3,TEXT(DN5,"yyyy") & "-" & TEXT(DN5,"yy")+1)) -> 2028-29 | DR3: =DT3 -> 2028-29 | DT3: =IF(MONTH(DR5)<=3,TEXT(DR5,"yyyy")-1 & "-" & TEXT(DR5,"yy"),IF(MONTH(DR5)>3,TEXT(DR5,"yyyy") & "-" & TEXT(DR5,"yy")+1)) -> 2028-29 | DV3: =DX3 -> 2028-29 | DX3: =IF(MONTH(DV5)<=3,TEXT(DV5,"yyyy")-1 & "-" & TEXT(DV5,"yy"),IF(MONTH(DV5)>3,TEXT(DV5,"yyyy") & "-" & TEXT(DV5,"yy")+1)) -> 2028-29 | DZ3: =EB3 -> 2028-29 | EB3: =IF(MONTH(DZ5)<=3,TEXT(DZ5,"yyyy")-1 & "-" & TEXT(DZ5,"yy"),IF(MONTH(DZ5)>3,TEXT(DZ5,"yyyy") & "-" & TEXT(DZ5,"yy")+1)) -> 2028-29 | ED3: =EF3 -> 2028-29 | EF3: =IF(MONTH(ED5)<=3,TEXT(ED5,"yyyy")-1 & "-" & TEXT(ED5,"yy"),IF(MONTH(ED5)>3,TEXT(ED5,"yyyy") & "-" & TEXT(ED5,"yy")+1)) -> 2028-29 | EH3: =EJ3 -> 2028-29 | EJ3: =IF(MONTH(EH5)<=3,TEXT(EH5,"yyyy")-1 & "-" & TEXT(EH5,"yy"),IF(MONTH(EH5)>3,TEXT(EH5,"yyyy") & "-" & TEXT(EH5,"yy")+1)) -> 2028-29 | EL3: =EN3 -> 2028-29 | EN3: =IF(MONTH(EL5)<=3,TEXT(EL5,"yyyy")-1 & "-" & TEXT(EL5,"yy"),IF(MONTH(EL5)>3,TEXT(EL5,"yyyy") & "-" & TEXT(EL5,"yy")+1)) -> 2028-29 | EP3: =ER3 -> 2028-29 | ER3: =IF(MONTH(EP5)<=3,TEXT(EP5,"yyyy")-1 & "-" & TEXT(EP5,"yy"),IF(MONTH(EP5)>3,TEXT(EP5,"yyyy") & "-" & TEXT(EP5,"yy")+1)) -> 2028-29 | ET3: =EV3 -> 2029-30 | EV3: =IF(MONTH(ET5)<=3,TEXT(ET5,"yyyy")-1 & "-" & TEXT(ET5,"yy"),IF(MONTH(ET5)>3,TEXT(ET5,"yyyy") & "-" & TEXT(ET5,"yy")+1)) -> 2029-30 | EX3: =EZ3 -> 2029-30 | EZ3: =IF(MONTH(EX5)<=3,TEXT(EX5,"yyyy")-1 & "-" & TEXT(EX5,"yy"),IF(MONTH(EX5)>3,TEXT(EX5,"yyyy") & "-" & TEXT(EX5,"yy")+1)) -> 2029-30 | FB3: =FD3 -> 2029-30 | FD3: =IF(MONTH(FB5)<=3,TEXT(FB5,"yyyy")-1 & "-" & TEXT(FB5,"yy"),IF(MONTH(FB5)>3,TEXT(FB5,"yyyy") & "-" & TEXT(FB5,"yy")+1)) -> 2029-30 | FF3: =FH3 -> 2029-30 | FH3: =IF(MONTH(FF5)<=3,TEXT(FF5,"yyyy")-1 & "-" & TEXT(FF5,"yy"),IF(MONTH(FF5)>3,TEXT(FF5,"yyyy") & "-" & TEXT(FF5,"yy")+1)) -> 2029-30 | FJ3: =FL3 -> 2029-30 | FL3: =IF(MONTH(FJ5)<=3,TEXT(FJ5,"yyyy")-1 & "-" & TEXT(FJ5,"yy"),IF(MONTH(FJ5)>3,TEXT(FJ5,"yyyy") & "-" & TEXT(FJ5,"yy")+1)) -> 2029-30 | FN3: =FP3 -> 2029-30 | FP3: =IF(MONTH(FN5)<=3,TEXT(FN5,"yyyy")-1 & "-" & TEXT(FN5,"yy"),IF(MONTH(FN5)>3,TEXT(FN5,"yyyy") & "-" & TEXT(FN5,"yy")+1)) -> 2029-30 | FR3: =FT3 -> 2029-30 | FT3: =IF(MONTH(FR5)<=3,TEXT(FR5,"yyyy")-1 & "-" & TEXT(FR5,"yy"),IF(MONTH(FR5)>3,TEXT(FR5,"yyyy") & "-" & TEXT(FR5,"yy")+1)) -> 2029-30 | FV3: =FX3 -> 2029-30 | FX3: =IF(MONTH(FV5)<=3,TEXT(FV5,"yyyy")-1 & "-" & TEXT(FV5,"yy"),IF(MONTH(FV5)>3,TEXT(FV5,"yyyy") & "-" & TEXT(FV5,"yy")+1)) -> 2029-30 | FZ3: =GB3 -> 2029-30 | GB3: =IF(MONTH(FZ5)<=3,TEXT(FZ5,"yyyy")-1 & "-" & TEXT(FZ5,"yy"),IF(MONTH(FZ5)>3,TEXT(FZ5,"yyyy") & "-" & TEXT(FZ5,"yy")+1)) -> 2029-30 | GD3: =GF3 -> 2029-30 | GF3: =IF(MONTH(GD5)<=3,TEXT(GD5,"yyyy")-1 & "-" & TEXT(GD5,"yy"),IF(MONTH(GD5)>3,TEXT(GD5,"yyyy") & "-" & TEXT(GD5,"yy")+1)) -> 2029-30 | GH3: =GJ3 -> 2029-30 | GJ3: =IF(MONTH(GH5)<=3,TEXT(GH5,"yyyy")-1 & "-" & TEXT(GH5,"yy"),IF(MONTH(GH5)>3,TEXT(GH5,"yyyy") & "-" & TEXT(GH5,"yy")+1)) -> 2029-30 | GL3: =GN3 -> 2029-30 | GN3: =IF(MONTH(GL5)<=3,TEXT(GL5,"yyyy")-1 & "-" & TEXT(GL5,"yy"),IF(MONTH(GL5)>3,TEXT(GL5,"yyyy") & "-" & TEXT(GL5,"yy")+1)) -> 2029-30 | GP3: =GR3 -> 2030-31 | GR3: =IF(MONTH(GP5)<=3,TEXT(GP5,"yyyy")-1 & "-" & TEXT(GP5,"yy"),IF(MONTH(GP5)>3,TEXT(GP5,"yyyy") & "-" & TEXT(GP5,"yy")+1)) -> 2030-31 | GT3: =GV3 -> 2030-31 | GV3: =IF(MONTH(GT5)<=3,TEXT(GT5,"yyyy")-1 & "-" & TEXT(GT5,"yy"),IF(MONTH(GT5)>3,TEXT(GT5,"yyyy") & "-" & TEXT(GT5,"yy")+1)) -> 2030-31 | GX3: =GZ3 -> 2030-31 | GZ3: =IF(MONTH(GX5)<=3,TEXT(GX5,"yyyy")-1 & "-" & TEXT(GX5,"yy"),IF(MONTH(GX5)>3,TEXT(GX5,"yyyy") & "-" & TEXT(GX5,"yy")+1)) -> 2030-31 | HB3: =HD3 -> 2030-31 | HD3: =IF(MONTH(HB5)<=3,TEXT(HB5,"yyyy")-1 & "-" & TEXT(HB5,"yy"),IF(MONTH(HB5)>3,TEXT(HB5,"yyyy") & "-" & TEXT(HB5,"yy")+1)) -> 2030-31 | HF3: =HH3 -> 2030-31 | HH3: =IF(MONTH(HF5)<=3,TEXT(HF5,"yyyy")-1 & "-" & TEXT(HF5,"yy"),IF(MONTH(HF5)>3,TEXT(HF5,"yyyy") & "-" & TEXT(HF5,"yy")+1)) -> 2030-31 | HJ3: =HL3 -> 2030-31 | HL3: =IF(MONTH(HJ5)<=3,TEXT(HJ5,"yyyy")-1 & "-" & TEXT(HJ5,"yy"),IF(MONTH(HJ5)>3,TEXT(HJ5,"yyyy") & "-" & TEXT(HJ5,"yy")+1)) -> 2030-31 | HN3: =HP3 -> 2030-31 | HP3: =IF(MONTH(HN5)<=3,TEXT(HN5,"yyyy")-1 & "-" & TEXT(HN5,"yy"),IF(MONTH(HN5)>3,TEXT(HN5,"yyyy") & "-" & TEXT(HN5,"yy")+1)) -> 2030-31 | HR3: =HT3 -> 2030-31 | HT3: =IF(MONTH(HR5)<=3,TEXT(HR5,"yyyy")-1 & "-" & TEXT(HR5,"yy"),IF(MONTH(HR5)>3,TEXT(HR5,"yyyy") & "-" & TEXT(HR5,"yy")+1)) -> 2030-31 | HV3: =HX3 -> 2030-31 | HX3: =IF(MONTH(HV5)<=3,TEXT(HV5,"yyyy")-1 & "-" & TEXT(HV5,"yy"),IF(MONTH(HV5)>3,TEXT(HV5,"yyyy") & "-" & TEXT(HV5,"yy")+1)) -> 2030-31 | HZ3: =IB3 -> 2030-31 | IB3: =IF(MONTH(HZ5)<=3,TEXT(HZ5,"yyyy")-1 & "-" & TEXT(HZ5,"yy"),IF(MONTH(HZ5)>3,TEXT(HZ5,"yyyy") & "-" & TEXT(HZ5,"yy")+1)) -> 2030-31 | ID3: =IF3 -> 2030-31 | IF3: =IF(MONTH(ID5)<=3,TEXT(ID5,"yyyy")-1 & "-" & TEXT(ID5,"yy"),IF(MONTH(ID5)>3,TEXT(ID5,"yyyy") & "-" & TEXT(ID5,"yy")+1)) -> 2030-31 | IH3: =IJ3 -> 2030-31 | IJ3: =IF(MONTH(IH5)<=3,TEXT(IH5,"yyyy")-1 & "-" & TEXT(IH5,"yy"),IF(MONTH(IH5)>3,TEXT(IH5,"yyyy") & "-" & TEXT(IH5,"yy")+1)) -> 2030-31
C4: Particulars | G4: Month - | H4: 1 | K4: Month - | L4: =H4+1 -> 2 | O4: Month - | P4: =L4+1 -> 3 | S4: Month - | T4: =P4+1 -> 4 | W4: Month - | X4: =T4+1 -> 5 | AA4: Month - | AB4: =X4+1 -> 6 | AE4: Month - | AF4: =AB4+1 -> 7 | AI4: Month - | AJ4: =AF4+1 -> 8 | AM4: Month - | AN4: =AJ4+1 -> 9 | AQ4: Month - | AR4: =AN4+1 -> 10 | AU4: Month - | AV4: =AR4+1 -> 11 | AY4: Month - | AZ4: =AV4+1 -> 12 | BC4: Month - | BD4: =AZ4+1 -> 13 | BG4: Month - | BH4: =BD4+1 -> 14 | BK4: Month - | BL4: =BH4+1 -> 15 | BO4: Month - | BP4: =BL4+1 -> 16 | BS4: Month - | BT4: =BP4+1 -> 17 | BW4: Month - | BX4: =BT4+1 -> 18 | CA4: Month - | CB4: =BX4+1 -> 19 | CE4: Month - | CF4: =CB4+1 -> 20 | CI4: Month - | CJ4: =CF4+1 -> 21 | CM4: Month - | CN4: =CJ4+1 -> 22 | CQ4: Month - | CR4: =CN4+1 -> 23 | CU4: Month - | CV4: =CR4+1 -> 24 | CY4: Month - | CZ4: =CV4+1 -> 25 | DC4: Month - | DD4: =CZ4+1 -> 26 | DG4: Month - | DH4: =DD4+1 -> 27 | DK4: Month - | DL4: =DH4+1 -> 28 | DO4: Month - | DP4: =DL4+1 -> 29 | DS4: Month - | DT4: =DP4+1 -> 30 | DW4: Month - | DX4: =DT4+1 -> 31 | EA4: Month - | EB4: =DX4+1 -> 32 | EE4: Month - | EF4: =EB4+1 -> 33 | EI4: Month - | EJ4: =EF4+1 -> 34 | EM4: Month - | EN4: =EJ4+1 -> 35 | EQ4: Month - | ER4: =EN4+1 -> 36 | EU4: Month - | EV4: =ER4+1 -> 37 | EY4: Month - | EZ4: =EV4+1 -> 38 | FC4: Month - | FD4: =EZ4+1 -> 39 | FG4: Month - | FH4: =FD4+1 -> 40 | FK4: Month - | FL4: =FH4+1 -> 41 | FO4: Month - | FP4: =FL4+1 -> 42 | FS4: Month - | FT4: =FP4+1 -> 43 | FW4: Month - | FX4: =FT4+1 -> 44 | GA4: Month - | GB4: =FX4+1 -> 45 | GE4: Month - | GF4: =GB4+1 -> 46 | GI4: Month - | GJ4: =GF4+1 -> 47 | GM4: Month - | GN4: =GJ4+1 -> 48 | GQ4: Month - | GR4: =GN4+1 -> 49 | GU4: Month - | GV4: =GR4+1 -> 50 | GY4: Month - | GZ4: =GV4+1 -> 51 | HC4: Month - | HD4: =GZ4+1 -> 52 | HG4: Month - | HH4: =HD4+1 -> 53 | HK4: Month - | HL4: =HH4+1 -> 54 | HO4: Month - | HP4: =HL4+1 -> 55 | HS4: Month - | HT4: =HP4+1 -> 56 | HW4: Month - | HX4: =HT4+1 -> 57 | IA4: Month - | IB4: =HX4+1 -> 58 | IE4: Month - | IF4: =IB4+1 -> 59 | II4: Month - | IJ4: =IF4+1 -> 60 | IL4: Year 1 | IP4: Year 2 | IT4: Year 3 | IX4: Year 4 | JB4: Year 5 | JF4: Year 6
F5: =EOMONTH('1. Basics'!$D$16,1) -> 46142 | J5: =EOMONTH($F$5,1) -> 46173 | N5: =EOMONTH($F$5,2) -> 46203 | R5: =EOMONTH($F$5,3) -> 46234 | V5: =EOMONTH($F$5,4) -> 46265 | Z5: =EOMONTH($F$5,5) -> 46295 | AD5: =EOMONTH($F$5,6) -> 46326 | AH5: =EOMONTH($F$5,7) -> 46356 | AL5: =EOMONTH($F$5,8) -> 46387 | AP5: =EOMONTH($F$5,9) -> 46418 | AT5: =EOMONTH($F$5,10) -> 46446 | AX5: =EOMONTH($F$5,11) -> 46477 | BB5: =EOMONTH($F$5,12) -> 46507 | BF5: =EOMONTH($F$5,13) -> 46538 | BJ5: =EOMONTH($F$5,14) -> 46568 | BN5: =EOMONTH($F$5,15) -> 46599 | BR5: =EOMONTH($F$5,16) -> 46630 | BV5: =EOMONTH($F$5,17) -> 46660 | BZ5: =EOMONTH($F$5,18) -> 46691 | CD5: =EOMONTH($F$5,19) -> 46721 | CH5: =EOMONTH($F$5,20) -> 46752 | CL5: =EOMONTH($F$5,21) -> 46783 | CP5: =EOMONTH($F$5,22) -> 46812 | CT5: =EOMONTH($F$5,23) -> 46843 | CX5: =EOMONTH($F$5,24) -> 46873 | DB5: =EOMONTH($F$5,25) -> 46904 | DF5: =EOMONTH($F$5,26) -> 46934 | DJ5: =EOMONTH($F$5,27) -> 46965 | DN5: =EOMONTH($F$5,28) -> 46996 | DR5: =EOMONTH($F$5,29) -> 47026 | DV5: =EOMONTH($F$5,30) -> 47057 | DZ5: =EOMONTH($F$5,31) -> 47087 | ED5: =EOMONTH($F$5,32) -> 47118 | EH5: =EOMONTH($F$5,33) -> 47149 | EL5: =EOMONTH($F$5,34) -> 47177 | EP5: =EOMONTH($F$5,35) -> 47208 | ET5: =EOMONTH($F$5,36) -> 47238 | EX5: =EOMONTH($F$5,37) -> 47269 | FB5: =EOMONTH($F$5,38) -> 47299 | FF5: =EOMONTH($F$5,39) -> 47330 | FJ5: =EOMONTH($F$5,40) -> 47361 | FN5: =EOMONTH($F$5,41) -> 47391 | FR5: =EOMONTH($F$5,42) -> 47422 | FV5: =EOMONTH($F$5,43) -> 47452 | FZ5: =EOMONTH($F$5,44) -> 47483 | GD5: =EOMONTH($F$5,45) -> 47514 | GH5: =EOMONTH($F$5,46) -> 47542 | GL5: =EOMONTH($F$5,47) -> 47573 | GP5: =EOMONTH($F$5,48) -> 47603 | GT5: =EOMONTH($F$5,49) -> 47634 | GX5: =EOMONTH($F$5,50) -> 47664 | HB5: =EOMONTH($F$5,51) -> 47695 | HF5: =EOMONTH($F$5,52) -> 47726 | HJ5: =EOMONTH($F$5,53) -> 47756 | HN5: =EOMONTH($F$5,54) -> 47787 | HR5: =EOMONTH($F$5,55) -> 47817 | HV5: =EOMONTH($F$5,56) -> 47848 | HZ5: =EOMONTH($F$5,57) -> 47879 | ID5: =EOMONTH($F$5,58) -> 47907 | IH5: =EOMONTH($F$5,59) -> 47938 | IL5: 2025-26 | IP5: 2026-27 | IT5: 2027-28 | IX5: 2028-29 | JB5: 2029-30 | JF5: 2030-31
C6: PHASE - I REVENUES | F6: Qty | G6: Per Unit Cost | H6: Total Revenue | J6: Qty | K6: Per Unit Cost | L6: Total Revenue | N6: Qty | O6: Per Unit Cost | P6: Total Revenue | R6: Qty | S6: Per Unit Cost | T6: Total Revenue | V6: Qty | W6: Per Unit Cost | X6: Total Revenue | Z6: Qty | AA6: Per Unit Cost | AB6: Total Revenue | AD6: Qty | AE6: Per Unit Cost | AF6: Total Revenue | AH6: Qty | AI6: Per Unit Cost | AJ6: Total Revenue | AL6: Qty | AM6: Per Unit Cost | AN6: Total Revenue | AP6: Qty | AQ6: Per Unit Cost | AR6: Total Revenue | AT6: Qty | AU6: Per Unit Cost | AV6: Total Revenue | AX6: Qty | AY6: Per Unit Cost | AZ6: Total Revenue | BB6: Qty | BC6: Per Unit Cost | BD6: Total Revenue | BF6: Qty | BG6: Per Unit Cost | BH6: Total Revenue | BJ6: Qty | BK6: Per Unit Cost | BL6: Total Revenue | BN6: Qty | BO6: Per Unit Cost | BP6: Total Revenue | BR6: Qty | BS6: Per Unit Cost | BT6: Total Revenue | BV6: Qty | BW6: Per Unit Cost | BX6: Total Revenue | BZ6: Qty | CA6: Per Unit Cost | CB6: Total Revenue | CD6: Qty | CE6: Per Unit Cost | CF6: Total Revenue | CH6: Qty | CI6: Per Unit Cost | CJ6: Total Revenue | CL6: Qty | CM6: Per Unit Cost | CN6: Total Revenue | CP6: Qty | CQ6: Per Unit Cost | CR6: Total Revenue | CT6: Qty | CU6: Per Unit Cost | CV6: Total Revenue | CX6: Qty | CY6: Per Unit Cost | CZ6: Total Revenue | DB6: Qty | DC6: Per Unit Cost | DD6: Total Revenue | DF6: Qty | DG6: Per Unit Cost | DH6: Total Revenue | DJ6: Qty | DK6: Per Unit Cost | DL6: Total Revenue | DN6: Qty | DO6: Per Unit Cost | DP6: Total Revenue | DR6: Qty | DS6: Per Unit Cost | DT6: Total Revenue | DV6: Qty | DW6: Per Unit Cost | DX6: Total Revenue | DZ6: Qty | EA6: Per Unit Cost | EB6: Total Revenue | ED6: Qty | EE6: Per Unit Cost | EF6: Total Revenue | EH6: Qty | EI6: Per Unit Cost | EJ6: Total Revenue | EL6: Qty | EM6: Per Unit Cost | EN6: Total Revenue | EP6: Qty | EQ6: Per Unit Cost | ER6: Total Revenue | ET6: Qty | EU6: Per Unit Cost | EV6: Total Revenue | EX6: Qty | EY6: Per Unit Cost | EZ6: Total Revenue | FB6: Qty | FC6: Per Unit Cost | FD6: Total Revenue | FF6: Qty | FG6: Per Unit Cost | FH6: Total Revenue | FJ6: Qty | FK6: Per Unit Cost | FL6: Total Revenue | FN6: Qty | FO6: Per Unit Cost | FP6: Total Revenue | FR6: Qty | FS6: Per Unit Cost | FT6: Total Revenue | FV6: Qty | FW6: Per Unit Cost | FX6: Total Revenue | FZ6: Qty | GA6: Per Unit Cost | GB6: Total Revenue | GD6: Qty | GE6: Per Unit Cost | GF6: Total Revenue | GH6: Qty | GI6: Per Unit Cost | GJ6: Total Revenue | GL6: Qty | GM6: Per Unit Cost | GN6: Total Revenue | GP6: Qty | GQ6: Per Unit Cost | GR6: Total Revenue | GT6: Qty | GU6: Per Unit Cost | GV6: Total Revenue | GX6: Qty | GY6: Per Unit Cost | GZ6: Total Revenue | HB6: Qty | HC6: Per Unit Cost | HD6: Total Revenue | HF6: Qty | HG6: Per Unit Cost | HH6: Total Revenue | HJ6: Qty | HK6: Per Unit Cost | HL6: Total Revenue | HN6: Qty | HO6: Per Unit Cost | HP6: Total Revenue | HR6: Qty | HS6: Per Unit Cost | HT6: Total Revenue | HV6: Qty | HW6: Per Unit Cost | HX6: Total Revenue | HZ6: Qty | IA6: Per Unit Cost | IB6: Total Revenue | ID6: Qty | IE6: Per Unit Cost | IF6: Total Revenue | IH6: Qty | II6: Per Unit Cost | IJ6: Total Revenue | IL6: Qty | IM6: Cost Per Month | IN6: Total Revenue | IP6: Qty | IQ6: Cost Per Month | IR6: Total Revenue | IT6: Qty | IU6: Cost Per Month | IV6: Total Revenue | IX6: Qty | IY6: Cost Per Month | IZ6: Total Revenue | JB6: Qty | JC6: Cost Per Month | JD6: Total Revenue | JF6: Qty | JG6: Cost Per Month | JH6: Total Revenue
C8: Services | D8: Sub Services | J8: ='A.I Revenue Streams - P1'!K10+100% -> 1.01 | K8: 1 | N8: =J8 -> 1.01 | O8: 1 | R8: =N8 -> 1.01 | S8: 1 | V8: =R8 -> 1.01 | W8: 1 | Z8: =V8 -> 1.01 | AA8: 1 | AD8: =Z8 -> 1.01 | AE8: 1 | AH8: =AD8 -> 1.01 | AI8: 1 | AL8: =AH8 -> 1.01 | AM8: 1 | AP8: 1.1 | AQ8: 1 | AT8: 1 | AU8: 1 | AX8: =AT8 -> 1 | AY8: 1 | BB8: ='A.I Revenue Streams - P1'!M10+100% -> 1.82 | BC8: 1 | BF8: 1 | BG8: 1 | BJ8: 1 | BK8: 1 | BN8: =BJ8 -> 1 | BO8: 1 | BR8: =BN8 -> 1 | BS8: 1 | BV8: =BR8 -> 1 | BW8: 1 | BZ8: =BV8 -> 1 | CA8: 1 | CD8: =BZ8 -> 1 | CE8: 1 | CH8: =CD8 -> 1 | CI8: 1 | CL8: 1 | CM8: 1 | CP8: 1 | CQ8: 1 | CT8: =CP8 -> 1 | CU8: 1 | CX8: ='A.I Revenue Streams - P1'!O10+100% -> 1.7 | CY8: 1 | DB8: 1 | DC8: 1 | DF8: =DB8 -> 1 | DG8: 1 | DJ8: =DF8 -> 1 | DK8: 1 | DN8: =DJ8 -> 1 | DO8: 1 | DR8: =DN8 -> 1 | DS8: 1 | DV8: =DR8 -> 1 | DW8: 1 | DZ8: =DV8 -> 1 | EA8: 1 | ED8: =DZ8 -> 1 | EE8: 1 | EH8: 1 | EI8: 1 | EL8: 1 | EM8: 1 | EP8: =EL8 -> 1 | EQ8: 1 | ET8: ='A.I Revenue Streams - P1'!Q10+100% -> 1.55 | EU8: 1 | EX8: 1 | EY8: 1 | FB8: =EX8 -> 1 | FC8: 1 | FF8: =FB8 -> 1 | FG8: 1 | FJ8: =FF8 -> 1 | FK8: 1 | FN8: =FJ8 -> 1 | FO8: 1 | FR8: =FN8 -> 1 | FS8: 1 | FV8: =FR8 -> 1 | FW8: 1 | FZ8: =FV8 -> 1 | GA8: 1 | GD8: 1 | GE8: 1 | GH8: 1 | GI8: 1 | GL8: =GH8 -> 1 | GM8: 1 | GP8: ='A.I Revenue Streams - P1'!S10+100% -> 1.45 | GQ8: 1 | GT8: 1 | GU8: 1 | GX8: =GT8 -> 1 | GY8: 1 | HB8: =GX8 -> 1 | HC8: 1 | HF8: =HB8 -> 1 | HG8: 1 | HJ8: =HF8 -> 1 | HK8: 1 | HN8: =HJ8 -> 1 | HO8: 1 | HR8: =HN8 -> 1 | HS8: 1 | HV8: =HR8 -> 1 | HW8: 1 | HZ8: 1 | IA8: 1 | ID8: 1 | IE8: 1 | IH8: =ID8 -> 1 | II8: 1 | IL8: ='A.I Revenue Streams - P2'!DI10+100% -> 1 | IM8: 1 | IP8: ='A.I Revenue Streams - P2'!DM10+100% -> 1 | IQ8: 1 | IT8: ='A.I Revenue Streams - P2'!DQ10+100% -> 1 | IU8: 1 | IX8: ='A.I Revenue Streams - P2'!DU10+100% -> 1 | IY8: 1 | JB8: ='A.I Revenue Streams - P2'!DY10+100% -> 1 | JC8: 1 | JF8: ='A.I Revenue Streams - P2'!EC10+100% -> 1 | JG8: 1
B9: 1 | C9: ='A.I Revenue Streams - P1'!D9 -> Doctor Consultations
B10: 1a | D10: ='A.I Revenue Streams - P1'!E10 -> Platform Access Fees | F10: ='A.I Revenue Streams - P1'!G10 -> 28000 | G10: ='A.I Revenue Streams - P1'!I10 -> 30 | H10: =F10*G10 -> 840000 | J10: =F10*$J$8 -> 28280 | K10: =G10*$K$8 -> 30 | L10: =J10*K10 -> 848400 | N10: =J10*$N$8 -> 28562.8 | O10: =K10*$O$8 -> 30 | P10: =N10*O10 -> 856884 | R10: =N10*$R$8 -> 28848.428 | S10: =O10*$S$8 -> 30 | T10: =R10*S10 -> 865452.84 | V10: =R10*$V$8 -> 29136.912 | W10: =S10*$W$8 -> 30 | X10: =V10*W10 -> 874107.37 | Z10: =V10*$Z$8 -> 29428.281 | AA10: =W10*$AA$8 -> 30 | AB10: =Z10*AA10 -> 882848.44 | AD10: =Z10*$AD$8 -> 29722.564 | AE10: =AA10*$AE$8 -> 30 | AF10: =AD10*AE10 -> 891676.93 | AH10: =AD10*$AH$8 -> 30019.79 | AI10: =AE10*$AI$8 -> 30 | AJ10: =AH10*AI10 -> 900593.7 | AL10: =AH10*$AL$8 -> 30319.988 | AM10: =AI10*$AM$8 -> 30 | AN10: =AL10*AM10 -> 909599.63 | AP10: =AL10*$AP$8 -> 33351.987 | AQ10: =AM10*$AQ$8 -> 30 | AR10: =AP10*AQ10 -> 1000559.6 | AT10: =AP10*$AT$8 -> 33351.987 | AU10: =AQ10*$AU$8 -> 30 | AV10: =AT10*AU10 -> 1000559.6 | AX10: =AT10*$AX$8 -> 33351.987 | AY10: =AU10*$AY$8 -> 30 | AZ10: =AX10*AY10 -> 1000559.6 | BB10: =AX10*$BB$8 -> 60700.615 | BC10: =AY10*$BC$8 -> 30 | BD10: =BB10*BC10 -> 1821018.5 | BF10: =BB10*$BF$8 -> 60700.615 | BG10: =BC10*$BG$8 -> 30 | BH10: =BF10*BG10 -> 1821018.5 | BJ10: =BF10*$BJ$8 -> 60700.615 | BK10: =BG10*$BK$8 -> 30 | BL10: =BJ10*BK10 -> 1821018.5 | BN10: =BJ10*$BN$8 -> 60700.615 | BO10: =BK10*$BO$8 -> 30 | BP10: =BN10*BO10 -> 1821018.5 | BR10: =BN10*$BR$8 -> 60700.615 | BS10: =BO10*$BS$8 -> 30 | BT10: =BR10*BS10 -> 1821018.5 | BV10: =BR10*$BV$8 -> 60700.615 | BW10: =BS10*$BW$8 -> 30 | BX10: =BV10*BW10 -> 1821018.5 | BZ10: =BV10*$BZ$8 -> 60700.615 | CA10: =BW10*$CA$8 -> 30 | CB10: =BZ10*CA10 -> 1821018.5 | CD10: =BZ10*$CD$8 -> 60700.615 | CE10: =CA10*$CE$8 -> 30 | CF10: =CD10*CE10 -> 1821018.5 | CH10: =CD10*$CH$8 -> 60700.615 | CI10: =CE10*$CI$8 -> 30 | CJ10: =CH10*CI10 -> 1821018.5 | CL10: =CH10*$CL$8 -> 60700.615 | CM10: =CI10*$CM$8 -> 30 | CN10: =CL10*CM10 -> 1821018.5 | CP10: =CL10*$CP$8 -> 60700.615 | CQ10: =CM10*$CQ$8 -> 30 | CR10: =CP10*CQ10 -> 1821018.5 | CT10: =CP10*$CT$8 -> 60700.615 | CU10: =CQ10*$CU$8 -> 30 | CV10: =CT10*CU10 -> 1821018.5 | CX10: =CT10*$CX$8 -> 103191.05 | CY10: =CU10*$CY$8 -> 30 | CZ10: =CX10*CY10 -> 3095731.4 | DB10: =CX10*$DB$8 -> 103191.05 | DC10: =CY10*$DC$8 -> 30 | DD10: =DB10*DC10 -> 3095731.4 | DF10: =DB10*$DF$8 -> 103191.05 | DG10: =DC10*$DG$8 -> 30 | DH10: =DF10*DG10 -> 3095731.4 | DJ10: =DF10*$DJ$8 -> 103191.05 | DK10: =DG10*$DK$8 -> 30 | DL10: =DJ10*DK10 -> 3095731.4 | DN10: =DJ10*$DN$8 -> 103191.05 | DO10: =DK10*$DO$8 -> 30 | DP10: =DN10*DO10 -> 3095731.4 | DR10: =DN10*$DR$8 -> 103191.05 | DS10: =DO10*$DS$8 -> 30 | DT10: =DR10*DS10 -> 3095731.4 | DV10: =DR10*$DV$8 -> 103191.05 | DW10: =DS10*$DW$8 -> 30 | DX10: =DV10*DW10 -> 3095731.4 | DZ10: =DV10*$DZ$8 -> 103191.05 | EA10: =DW10*$EA$8 -> 30 | EB10: =DZ10*EA10 -> 3095731.4 | ED10: =DZ10*$ED$8 -> 103191.05 | EE10: =EA10*$EE$8 -> 30 | EF10: =ED10*EE10 -> 3095731.4 | EH10: =ED10*$EH$8 -> 103191.05 | EI10: =EE10*$EI$8 -> 30 | EJ10: =EH10*EI10 -> 3095731.4 | EL10: =EH10*$EL$8 -> 103191.05 | EM10: =EI10*$EM$8 -> 30 | EN10: =EL10*EM10 -> 3095731.4 | EP10: =EL10*$EP$8 -> 103191.05 | EQ10: =EM10*$EQ$8 -> 30 | ER10: =EP10*EQ10 -> 3095731.4 | ET10: =EP10*$ET$8 -> 159946.12 | EU10: =EQ10*$EU$8 -> 30 | EV10: =ET10*EU10 -> 4798383.7 | EX10: =ET10*$EX$8 -> 159946.12 | EY10: =EU10*$EY$8 -> 30 | EZ10: =EX10*EY10 -> 4798383.7 | FB10: =EX10*$FB$8 -> 159946.12 | FC10: =EY10*$FC$8 -> 30 | FD10: =FB10*FC10 -> 4798383.7 | FF10: =FB10*$FF$8 -> 159946.12 | FG10: =FC10*$FG$8 -> 30 | FH10: =FF10*FG10 -> 4798383.7 | FJ10: =FF10*$FJ$8 -> 159946.12 | FK10: =FG10*$FK$8 -> 30 | FL10: =FJ10*FK10 -> 4798383.7 | FN10: =FJ10*$FN$8 -> 159946.12 | FO10: =FK10*$FO$8 -> 30 | FP10: =FN10*FO10 -> 4798383.7 | FR10: =FN10*$FR$8 -> 159946.12 | FS10: =FO10*$FS$8 -> 30 | FT10: =FR10*FS10 -> 4798383.7 | FV10: =FR10*$FV$8 -> 159946.12 | FW10: =FS10*$FW$8 -> 30 | FX10: =FV10*FW10 -> 4798383.7 | FZ10: =FV10*$FZ$8 -> 159946.12 | GA10: =FW10*$GA$8 -> 30 | GB10: =FZ10*GA10 -> 4798383.7 | GD10: =FZ10*$GD$8 -> 159946.12 | GE10: =GA10*$GE$8 -> 30 | GF10: =GD10*GE10 -> 4798383.7 | GH10: =GD10*$GH$8 -> 159946.12 | GI10: =GE10*$GI$8 -> 30 | GJ10: =GH10*GI10 -> 4798383.7 | GL10: =GH10*$GL$8 -> 159946.12 | GM10: =GI10*$GM$8 -> 30 | GN10: =GL10*GM10 -> 4798383.7 | GP10: =GL10*$GP$8 -> 231921.88 | GQ10: =GM10*$GQ$8 -> 30 | GR10: =GP10*GQ10 -> 6957656.3 | GT10: =GP10*$GT$8 -> 231921.88 | GU10: =GQ10*$GU$8 -> 30 | GV10: =GT10*GU10 -> 6957656.3 | GX10: =GT10*$GX$8 -> 231921.88 | GY10: =GU10*$GY$8 -> 30 | GZ10: =GX10*GY10 -> 6957656.3 | HB10: =GX10*$HB$8 -> 231921.88 | HC10: =GY10*$HC$8 -> 30 | HD10: =HB10*HC10 -> 6957656.3 | HF10: =HB10*$HF$8 -> 231921.88 | HG10: =HC10*$HG$8 -> 30 | HH10: =HF10*HG10 -> 6957656.3 | HJ10: =HF10*$HJ$8 -> 231921.88 | HK10: =HG10*$HK$8 -> 30 | HL10: =HJ10*HK10 -> 6957656.3 | HN10: =HJ10*$HN$8 -> 231921.88 | HO10: =HK10*$HO$8 -> 30 | HP10: =HN10*HO10 -> 6957656.3 | HR10: =HN10*$HR$8 -> 231921.88 | HS10: =HO10*$HS$8 -> 30 | HT10: =HR10*HS10 -> 6957656.3 | HV10: =HR10*$HV$8 -> 231921.88 | HW10: =HS10*$HW$8 -> 30 | HX10: =HV10*HW10 -> 6957656.3 | HZ10: =HV10*$HZ$8 -> 231921.88 | IA10: =HW10*$IA$8 -> 30 | IB10: =HZ10*IA10 -> 6957656.3 | ID10: =HZ10*$ID$8 -> 231921.88 | IE10: =IA10*$IE$8 -> 30 | IF10: =ID10*IE10 -> 6957656.3 | IH10: =ID10*$IH$8 -> 231921.88 | II10: =IE10*$II$8 -> 30 | IJ10: =IH10*II10 -> 6957656.3 | IL10: =SUMIFS($F10:$IK10,$F$3:$IK$3,IL$5,$F$6:$IK$6,IL$6) -> 0 | IM10: 0 | IN10: =SUMIFS($F10:$IK10,$F$3:$IK$3,IL$5,$F$6:$IK$6,IN$6) -> 0 | IP10: =SUMIFS($F10:$IK10,$F$3:$IK$3,IP$5,$F$6:$IK$6,IP$6) -> 362374.72 | IQ10: =IR10/IP10 -> 30 | IR10: =SUMIFS($F10:$IK10,$F$3:$IK$3,IP$5,$F$6:$IK$6,IR$6) -> 10871242 | IT10: =SUMIFS($F10:$IK10,$F$3:$IK$3,IT$5,$F$6:$IK$6,IT$6) -> 728407.39 | IU10: =IV10/IT10 -> 30 | IV10: =SUMIFS($F10:$IK10,$F$3:$IK$3,IT$5,$F$6:$IK$6,IV$6) -> 21852222 | IX10: =SUMIFS($F10:$IK10,$F$3:$IK$3,IX$5,$F$6:$IK$6,IX$6) -> 1238292.6 | IY10: =IZ10/IX10 -> 30 | IZ10: =SUMIFS($F10:$IK10,$F$3:$IK$3,IX$5,$F$6:$IK$6,IZ$6) -> 37148777 | JB10: =SUMIFS($F10:$IK10,$F$3:$IK$3,JB$5,$F$6:$IK$6,JB$6) -> 1919353.5 | JC10: =JD10/JB10 -> 30 | JD10: =SUMIFS($F10:$IK10,$F$3:$IK$3,JB$5,$F$6:$IK$6,JD$6) -> 57580604 | JF10: =SUMIFS($F10:$IK10,$F$3:$IK$3,JF$5,$F$6:$IK$6,JF$6) -> 2783062.5 | JG10: =JH10/JF10 -> 30 | JH10: =SUMIFS($F10:$IK10,$F$3:$IK$3,JF$5,$F$6:$IK$6,JH$6) -> 83491876
B11: 1b | D11: ='A.I Revenue Streams - P1'!E11 -> 0 | F11: 0 | G11: ='A.I Revenue Streams - P1'!I11 -> 0 | H11: =F11*G11 -> 0 | J11: =F11*$J$8 -> 0 | K11: =G11*$K$8 -> 0 | L11: =J11*K11 -> 0 | N11: =J11*$N$8 -> 0 | O11: =K11*$O$8 -> 0 | P11: =N11*O11 -> 0 | R11: ='A.I Revenue Streams - P1'!G11 -> 0 | S11: =O11*$S$8 -> 0 | T11: =R11*S11 -> 0 | V11: =R11*$V$8 -> 0 | W11: =S11*$W$8 -> 0 | X11: =V11*W11 -> 0 | Z11: =V11*$Z$8 -> 0 | AA11: =W11*$AA$8 -> 0 | AB11: =Z11*AA11 -> 0 | AD11: =Z11*$AD$8 -> 0 | AE11: =AA11*$AE$8 -> 0 | AF11: =AD11*AE11 -> 0 | AH11: =AD11*$AH$8 -> 0 | AI11: =AE11*$AI$8 -> 0 | AJ11: =AH11*AI11 -> 0 | AL11: =AH11*$AL$8 -> 0 | AM11: =AI11*$AM$8 -> 0 | AN11: =AL11*AM11 -> 0 | AP11: =AL11*$AP$8 -> 0 | AQ11: =AM11*$AQ$8 -> 0 | AR11: =AP11*AQ11 -> 0 | AT11: =AP11*$AT$8 -> 0 | AU11: =AQ11*$AU$8 -> 0 | AV11: =AT11*AU11 -> 0 | AX11: =AT11*$AX$8 -> 0 | AY11: =AU11*$AY$8 -> 0 | AZ11: =AX11*AY11 -> 0 | BB11: =AX11*$BB$8 -> 0 | BC11: =AY11*$BC$8 -> 0 | BD11: =BB11*BC11 -> 0 | BF11: =BB11*$BF$8 -> 0 | BG11: =BC11*$BG$8 -> 0 | BH11: =BF11*BG11 -> 0 | BJ11: =BF11*$BJ$8 -> 0 | BK11: =BG11*$BK$8 -> 0 | BL11: =BJ11*BK11 -> 0 | BN11: =BJ11*$BN$8 -> 0 | BO11: =BK11*$BO$8 -> 0 | BP11: =BN11*BO11 -> 0 | BR11: =BN11*$BR$8 -> 0 | BS11: =BO11*$BS$8 -> 0 | BT11: =BR11*BS11 -> 0 | BV11: =BR11*$BV$8 -> 0 | BW11: =BS11*$BW$8 -> 0 | BX11: =BV11*BW11 -> 0 | BZ11: =BV11*$BZ$8 -> 0 | CA11: =BW11*$CA$8 -> 0 | CB11: =BZ11*CA11 -> 0 | CD11: =BZ11*$CD$8 -> 0 | CE11: =CA11*$CE$8 -> 0 | CF11: =CD11*CE11 -> 0 | CH11: =CD11*$CH$8 -> 0 | CI11: =CE11*$CI$8 -> 0 | CJ11: =CH11*CI11 -> 0 | CL11: =CH11*$CL$8 -> 0 | CM11: =CI11*$CM$8 -> 0 | CN11: =CL11*CM11 -> 0 | CP11: =CL11*$CP$8 -> 0 | CQ11: =CM11*$CQ$8 -> 0 | CR11: =CP11*CQ11 -> 0 | CT11: =CP11*$CT$8 -> 0 | CU11: =CQ11*$CU$8 -> 0 | CV11: =CT11*CU11 -> 0 | CX11: =CT11*$CX$8 -> 0 | CY11: =CU11*$CY$8 -> 0 | CZ11: =CX11*CY11 -> 0 | DB11: =CX11*$DB$8 -> 0 | DC11: =CY11*$DC$8 -> 0 | DD11: =DB11*DC11 -> 0 | DF11: =DB11*$DF$8 -> 0 | DG11: =DC11*$DG$8 -> 0 | DH11: =DF11*DG11 -> 0 | DJ11: =DF11*$DJ$8 -> 0 | DK11: =DG11*$DK$8 -> 0 | DL11: =DJ11*DK11 -> 0 | DN11: =DJ11*$DN$8 -> 0 | DO11: =DK11*$DO$8 -> 0 | DP11: =DN11*DO11 -> 0 | DR11: =DN11*$DR$8 -> 0 | DS11: =DO11*$DS$8 -> 0 | DT11: =DR11*DS11 -> 0 | DV11: =DR11*$DV$8 -> 0 | DW11: =DS11*$DW$8 -> 0 | DX11: =DV11*DW11 -> 0 | DZ11: =DV11*$DZ$8 -> 0 | EA11: =DW11*$EA$8 -> 0 | EB11: =DZ11*EA11 -> 0 | ED11: =DZ11*$ED$8 -> 0 | EE11: =EA11*$EE$8 -> 0 | EF11: =ED11*EE11 -> 0 | EH11: =ED11*$EH$8 -> 0 | EI11: =EE11*$EI$8 -> 0 | EJ11: =EH11*EI11 -> 0 | EL11: =EH11*$EL$8 -> 0 | EM11: =EI11*$EM$8 -> 0 | EN11: =EL11*EM11 -> 0 | EP11: =EL11*$EP$8 -> 0 | EQ11: =EM11*$EQ$8 -> 0 | ER11: =EP11*EQ11 -> 0 | ET11: =EP11*$ET$8 -> 0 | EU11: =EQ11*$EU$8 -> 0 | EV11: =ET11*EU11 -> 0 | EX11: =ET11*$EX$8 -> 0 | EY11: =EU11*$EY$8 -> 0 | EZ11: =EX11*EY11 -> 0 | FB11: =EX11*$FB$8 -> 0 | FC11: =EY11*$FC$8 -> 0 | FD11: =FB11*FC11 -> 0 | FF11: =FB11*$FF$8 -> 0 | FG11: =FC11*$FG$8 -> 0 | FH11: =FF11*FG11 -> 0 | FJ11: =FF11*$FJ$8 -> 0 | FK11: =FG11*$FK$8 -> 0 | FL11: =FJ11*FK11 -> 0 | FN11: =FJ11*$FN$8 -> 0 | FO11: =FK11*$FO$8 -> 0 | FP11: =FN11*FO11 -> 0 | FR11: =FN11*$FR$8 -> 0 | FS11: =FO11*$FS$8 -> 0 | FT11: =FR11*FS11 -> 0 | FV11: =FR11*$FV$8 -> 0 | FW11: =FS11*$FW$8 -> 0 | FX11: =FV11*FW11 -> 0 | FZ11: =FV11*$FZ$8 -> 0 | GA11: =FW11*$GA$8 -> 0 | GB11: =FZ11*GA11 -> 0 | GD11: =FZ11*$GD$8 -> 0 | GE11: =GA11*$GE$8 -> 0 | GF11: =GD11*GE11 -> 0 | GH11: =GD11*$GH$8 -> 0 | GI11: =GE11*$GI$8 -> 0 | GJ11: =GH11*GI11 -> 0 | GL11: =GH11*$GL$8 -> 0 | GM11: =GI11*$GM$8 -> 0 | GN11: =GL11*GM11 -> 0 | GP11: =GL11*$GP$8 -> 0 | GQ11: =GM11*$GQ$8 -> 0 | GR11: =GP11*GQ11 -> 0 | GT11: =GP11*$GT$8 -> 0 | GU11: =GQ11*$GU$8 -> 0 | GV11: =GT11*GU11 -> 0 | GX11: =GT11*$GX$8 -> 0 | GY11: =GU11*$GY$8 -> 0 | GZ11: =GX11*GY11 -> 0 | HB11: =GX11*$HB$8 -> 0 | HC11: =GY11*$HC$8 -> 0 | HD11: =HB11*HC11 -> 0 | HF11: =HB11*$HF$8 -> 0 | HG11: =HC11*$HG$8 -> 0 | HH11: =HF11*HG11 -> 0 | HJ11: =HF11*$HJ$8 -> 0 | HK11: =HG11*$HK$8 -> 0 | HL11: =HJ11*HK11 -> 0 | HN11: =HJ11*$HN$8 -> 0 | HO11: =HK11*$HO$8 -> 0 | HP11: =HN11*HO11 -> 0 | HR11: =HN11*$HR$8 -> 0 | HS11: =HO11*$HS$8 -> 0 | HT11: =HR11*HS11 -> 0 | HV11: =HR11*$HV$8 -> 0 | HW11: =HS11*$HW$8 -> 0 | HX11: =HV11*HW11 -> 0 | HZ11: =HV11*$HZ$8 -> 0 | IA11: =HW11*$IA$8 -> 0 | IB11: =HZ11*IA11 -> 0 | ID11: =HZ11*$ID$8 -> 0 | IE11: =IA11*$IE$8 -> 0 | IF11: =ID11*IE11 -> 0 | IH11: =ID11*$IH$8 -> 0 | II11: =IE11*$II$8 -> 0 | IJ11: =IH11*II11 -> 0 | IL11: =SUMIFS($F11:$IK11,$F$3:$IK$3,IL$5,$F$6:$IK$6,IL$6) -> 0 | IM11: 0 | IN11: =SUMIFS($F11:$IK11,$F$3:$IK$3,IL$5,$F$6:$IK$6,IN$6) -> 0 | IP11: =SUMIFS($F11:$IK11,$F$3:$IK$3,IP$5,$F$6:$IK$6,IP$6) -> 0 | IQ11: =IR11/IP11 -> #DIV/0! | IR11: =SUMIFS($F11:$IK11,$F$3:$IK$3,IP$5,$F$6:$IK$6,IR$6) -> 0 | IT11: =SUMIFS($F11:$IK11,$F$3:$IK$3,IT$5,$F$6:$IK$6,IT$6) -> 0 | IU11: =IV11/IT11 -> #DIV/0! | IV11: =SUMIFS($F11:$IK11,$F$3:$IK$3,IT$5,$F$6:$IK$6,IV$6) -> 0 | IX11: =SUMIFS($F11:$IK11,$F$3:$IK$3,IX$5,$F$6:$IK$6,IX$6) -> 0 | IY11: =IZ11/IX11 -> #DIV/0! | IZ11: =SUMIFS($F11:$IK11,$F$3:$IK$3,IX$5,$F$6:$IK$6,IZ$6) -> 0 | JB11: =SUMIFS($F11:$IK11,$F$3:$IK$3,JB$5,$F$6:$IK$6,JB$6) -> 0 | JC11: =JD11/JB11 -> #DIV/0! | JD11: =SUMIFS($F11:$IK11,$F$3:$IK$3,JB$5,$F$6:$IK$6,JD$6) -> 0 | JF11: =SUMIFS($F11:$IK11,$F$3:$IK$3,JF$5,$F$6:$IK$6,JF$6) -> 0 | JG11: =JH11/JF11 -> #DIV/0! | JH11: =SUMIFS($F11:$IK11,$F$3:$IK$3,JF$5,$F$6:$IK$6,JH$6) -> 0
B12: 1c | D12: ='A.I Revenue Streams - P1'!E12 -> 0 | F12: ='A.I Revenue Streams - P1'!G12 -> 0 | G12: ='A.I Revenue Streams - P1'!I12 -> 0 | H12: =F12*G12 -> 0 | J12: =F12*$J$8 -> 0 | K12: =G12*$K$8 -> 0 | L12: =J12*K12 -> 0 | N12: =J12*$N$8 -> 0 | O12: =K12*$O$8 -> 0 | P12: =N12*O12 -> 0 | R12: =N12*$R$8 -> 0 | S12: =O12*$S$8 -> 0 | T12: =R12*S12 -> 0 | V12: =R12*$V$8 -> 0 | W12: =S12*$W$8 -> 0 | X12: =V12*W12 -> 0 | Z12: =V12*$Z$8 -> 0 | AA12: =W12*$AA$8 -> 0 | AB12: =Z12*AA12 -> 0 | AD12: =Z12*$AD$8 -> 0 | AE12: =AA12*$AE$8 -> 0 | AF12: =AD12*AE12 -> 0 | AH12: =AD12*$AH$8 -> 0 | AI12: =AE12*$AI$8 -> 0 | AJ12: =AH12*AI12 -> 0 | AL12: =AH12*$AL$8 -> 0 | AM12: =AI12*$AM$8 -> 0 | AN12: =AL12*AM12 -> 0 | AP12: =AL12*$AP$8 -> 0 | AQ12: =AM12*$AQ$8 -> 0 | AR12: =AP12*AQ12 -> 0 | AT12: =AP12*$AT$8 -> 0 | AU12: =AQ12*$AU$8 -> 0 | AV12: =AT12*AU12 -> 0 | AX12: =AT12*$AX$8 -> 0 | AY12: =AU12*$AY$8 -> 0 | AZ12: =AX12*AY12 -> 0 | BB12: =AX12*$BB$8 -> 0 | BC12: =AY12*$BC$8 -> 0 | BD12: =BB12*BC12 -> 0 | BF12: =BB12*$BF$8 -> 0 | BG12: =BC12*$BG$8 -> 0 | BH12: =BF12*BG12 -> 0 | BJ12: =BF12*$BJ$8 -> 0 | BK12: =BG12*$BK$8 -> 0 | BL12: =BJ12*BK12 -> 0 | BN12: =BJ12*$BN$8 -> 0 | BO12: =BK12*$BO$8 -> 0 | BP12: =BN12*BO12 -> 0 | BR12: =BN12*$BR$8 -> 0 | BS12: =BO12*$BS$8 -> 0 | BT12: =BR12*BS12 -> 0 | BV12: =BR12*$BV$8 -> 0 | BW12: =BS12*$BW$8 -> 0 | BX12: =BV12*BW12 -> 0 | BZ12: =BV12*$BZ$8 -> 0 | CA12: =BW12*$CA$8 -> 0 | CB12: =BZ12*CA12 -> 0 | CD12: =BZ12*$CD$8 -> 0 | CE12: =CA12*$CE$8 -> 0 | CF12: =CD12*CE12 -> 0 | CH12: =CD12*$CH$8 -> 0 | CI12: =CE12*$CI$8 -> 0 | CJ12: =CH12*CI12 -> 0 | CL12: =CH12*$CL$8 -> 0 | CM12: =CI12*$CM$8 -> 0 | CN12: =CL12*CM12 -> 0 | CP12: =CL12*$CP$8 -> 0 | CQ12: =CM12*$CQ$8 -> 0 | CR12: =CP12*CQ12 -> 0 | CT12: =CP12*$CT$8 -> 0 | CU12: =CQ12*$CU$8 -> 0 | CV12: =CT12*CU12 -> 0 | CX12: =CT12*$CX$8 -> 0 | CY12: =CU12*$CY$8 -> 0 | CZ12: =CX12*CY12 -> 0 | DB12: =CX12*$DB$8 -> 0 | DC12: =CY12*$DC$8 -> 0 | DD12: =DB12*DC12 -> 0 | DF12: =DB12*$DF$8 -> 0 | DG12: =DC12*$DG$8 -> 0 | DH12: =DF12*DG12 -> 0 | DJ12: =DF12*$DJ$8 -> 0 | DK12: =DG12*$DK$8 -> 0 | DL12: =DJ12*DK12 -> 0 | DN12: =DJ12*$DN$8 -> 0 | DO12: =DK12*$DO$8 -> 0 | DP12: =DN12*DO12 -> 0 | DR12: =DN12*$DR$8 -> 0 | DS12: =DO12*$DS$8 -> 0 | DT12: =DR12*DS12 -> 0 | DV12: =DR12*$DV$8 -> 0 | DW12: =DS12*$DW$8 -> 0 | DX12: =DV12*DW12 -> 0 | DZ12: =DV12*$DZ$8 -> 0 | EA12: =DW12*$EA$8 -> 0 | EB12: =DZ12*EA12 -> 0 | ED12: =DZ12*$ED$8 -> 0 | EE12: =EA12*$EE$8 -> 0 | EF12: =ED12*EE12 -> 0 | EH12: =ED12*$EH$8 -> 0 | EI12: =EE12*$EI$8 -> 0 | EJ12: =EH12*EI12 -> 0 | EL12: =EH12*$EL$8 -> 0 | EM12: =EI12*$EM$8 -> 0 | EN12: =EL12*EM12 -> 0 | EP12: =EL12*$EP$8 -> 0 | EQ12: =EM12*$EQ$8 -> 0 | ER12: =EP12*EQ12 -> 0 | ET12: =EP12*$ET$8 -> 0 | EU12: =EQ12*$EU$8 -> 0 | EV12: =ET12*EU12 -> 0 | EX12: =ET12*$EX$8 -> 0 | EY12: =EU12*$EY$8 -> 0 | EZ12: =EX12*EY12 -> 0 | FB12: =EX12*$FB$8 -> 0 | FC12: =EY12*$FC$8 -> 0 | FD12: =FB12*FC12 -> 0 | FF12: =FB12*$FF$8 -> 0 | FG12: =FC12*$FG$8 -> 0 | FH12: =FF12*FG12 -> 0 | FJ12: =FF12*$FJ$8 -> 0 | FK12: =FG12*$FK$8 -> 0 | FL12: =FJ12*FK12 -> 0 | FN12: =FJ12*$FN$8 -> 0 | FO12: =FK12*$FO$8 -> 0 | FP12: =FN12*FO12 -> 0 | FR12: =FN12*$FR$8 -> 0 | FS12: =FO12*$FS$8 -> 0 | FT12: =FR12*FS12 -> 0 | FV12: =FR12*$FV$8 -> 0 | FW12: =FS12*$FW$8 -> 0 | FX12: =FV12*FW12 -> 0 | FZ12: =FV12*$FZ$8 -> 0 | GA12: =FW12*$GA$8 -> 0 | GB12: =FZ12*GA12 -> 0 | GD12: =FZ12*$GD$8 -> 0 | GE12: =GA12*$GE$8 -> 0 | GF12: =GD12*GE12 -> 0 | GH12: =GD12*$GH$8 -> 0 | GI12: =GE12*$GI$8 -> 0 | GJ12: =GH12*GI12 -> 0 | GL12: =GH12*$GL$8 -> 0 | GM12: =GI12*$GM$8 -> 0 | GN12: =GL12*GM12 -> 0 | GP12: =GL12*$GP$8 -> 0 | GQ12: =GM12*$GQ$8 -> 0 | GR12: =GP12*GQ12 -> 0 | GT12: =GP12*$GT$8 -> 0 | GU12: =GQ12*$GU$8 -> 0 | GV12: =GT12*GU12 -> 0 | GX12: =GT12*$GX$8 -> 0 | GY12: =GU12*$GY$8 -> 0 | GZ12: =GX12*GY12 -> 0 | HB12: =GX12*$HB$8 -> 0 | HC12: =GY12*$HC$8 -> 0 | HD12: =HB12*HC12 -> 0 | HF12: =HB12*$HF$8 -> 0 | HG12: =HC12*$HG$8 -> 0 | HH12: =HF12*HG12 -> 0 | HJ12: =HF12*$HJ$8 -> 0 | HK12: =HG12*$HK$8 -> 0 | HL12: =HJ12*HK12 -> 0 | HN12: =HJ12*$HN$8 -> 0 | HO12: =HK12*$HO$8 -> 0 | HP12: =HN12*HO12 -> 0 | HR12: =HN12*$HR$8 -> 0 | HS12: =HO12*$HS$8 -> 0 | HT12: =HR12*HS12 -> 0 | HV12: =HR12*$HV$8 -> 0 | HW12: =HS12*$HW$8 -> 0 | HX12: =HV12*HW12 -> 0 | HZ12: =HV12*$HZ$8 -> 0 | IA12: =HW12*$IA$8 -> 0 | IB12: =HZ12*IA12 -> 0 | ID12: =HZ12*$ID$8 -> 0 | IE12: =IA12*$IE$8 -> 0 | IF12: =ID12*IE12 -> 0 | IH12: =ID12*$IH$8 -> 0 | II12: =IE12*$II$8 -> 0 | IJ12: =IH12*II12 -> 0 | IL12: =SUMIFS($F12:$IK12,$F$3:$IK$3,IL$5,$F$6:$IK$6,IL$6) -> 0 | IM12: 0 | IN12: =SUMIFS($F12:$IK12,$F$3:$IK$3,IL$5,$F$6:$IK$6,IN$6) -> 0 | IP12: =SUMIFS($F12:$IK12,$F$3:$IK$3,IP$5,$F$6:$IK$6,IP$6) -> 0 | IQ12: 0 | IR12: =SUMIFS($F12:$IK12,$F$3:$IK$3,IP$5,$F$6:$IK$6,IR$6) -> 0 | IT12: =SUMIFS($F12:$IK12,$F$3:$IK$3,IT$5,$F$6:$IK$6,IT$6) -> 0 | IU12: 0 | IV12: =SUMIFS($F12:$IK12,$F$3:$IK$3,IT$5,$F$6:$IK$6,IV$6) -> 0 | IX12: =SUMIFS($F12:$IK12,$F$3:$IK$3,IX$5,$F$6:$IK$6,IX$6) -> 0 | IY12: 0 | IZ12: =SUMIFS($F12:$IK12,$F$3:$IK$3,IX$5,$F$6:$IK$6,IZ$6) -> 0 | JB12: =SUMIFS($F12:$IK12,$F$3:$IK$3,JB$5,$F$6:$IK$6,JB$6) -> 0 | JC12: 0 | JD12: =SUMIFS($F12:$IK12,$F$3:$IK$3,JB$5,$F$6:$IK$6,JD$6) -> 0 | JF12: =SUMIFS($F12:$IK12,$F$3:$IK$3,JF$5,$F$6:$IK$6,JF$6) -> 0 | JG12: 0 | JH12: =SUMIFS($F12:$IK12,$F$3:$IK$3,JF$5,$F$6:$IK$6,JH$6) -> 0
B13: 1d | D13: ='A.I Revenue Streams - P1'!E13 -> 0 | F13: ='A.I Revenue Streams - P1'!G13 -> 0 | G13: ='A.I Revenue Streams - P1'!I13 -> 0 | H13: =F13*G13 -> 0 | J13: =F13*$J$8 -> 0 | K13: =G13*$K$8 -> 0 | L13: =J13*K13 -> 0 | N13: =J13*$N$8 -> 0 | O13: =K13*$O$8 -> 0 | P13: =N13*O13 -> 0 | R13: =N13*$R$8 -> 0 | S13: =O13*$S$8 -> 0 | T13: =R13*S13 -> 0 | V13: =R13*$V$8 -> 0 | W13: =S13*$W$8 -> 0 | X13: =V13*W13 -> 0 | Z13: =V13*$Z$8 -> 0 | AA13: =W13*$AA$8 -> 0 | AB13: =Z13*AA13 -> 0 | AD13: =Z13*$AD$8 -> 0 | AE13: =AA13*$AE$8 -> 0 | AF13: =AD13*AE13 -> 0 | AH13: =AD13*$AH$8 -> 0 | AI13: =AE13*$AI$8 -> 0 | AJ13: =AH13*AI13 -> 0 | AL13: =AH13*$AL$8 -> 0 | AM13: =AI13*$AM$8 -> 0 | AN13: =AL13*AM13 -> 0 | AP13: =AL13*$AP$8 -> 0 | AQ13: =AM13*$AQ$8 -> 0 | AR13: =AP13*AQ13 -> 0 | AT13: =AP13*$AT$8 -> 0 | AU13: =AQ13*$AU$8 -> 0 | AV13: =AT13*AU13 -> 0 | AX13: =AT13*$AX$8 -> 0 | AY13: =AU13*$AY$8 -> 0 | AZ13: =AX13*AY13 -> 0 | BB13: =AX13*$BB$8 -> 0 | BC13: =AY13*$BC$8 -> 0 | BD13: =BB13*BC13 -> 0 | BF13: =BB13*$BF$8 -> 0 | BG13: =BC13*$BG$8 -> 0 | BH13: =BF13*BG13 -> 0 | BJ13: =BF13*$BJ$8 -> 0 | BK13: =BG13*$BK$8 -> 0 | BL13: =BJ13*BK13 -> 0 | BN13: =BJ13*$BN$8 -> 0 | BO13: =BK13*$BO$8 -> 0 | BP13: =BN13*BO13 -> 0 | BR13: =BN13*$BR$8 -> 0 | BS13: =BO13*$BS$8 -> 0 | BT13: =BR13*BS13 -> 0 | BV13: =BR13*$BV$8 -> 0 | BW13: =BS13*$BW$8 -> 0 | BX13: =BV13*BW13 -> 0 | BZ13: =BV13*$BZ$8 -> 0 | CA13: =BW13*$CA$8 -> 0 | CB13: =BZ13*CA13 -> 0 | CD13: =BZ13*$CD$8 -> 0 | CE13: =CA13*$CE$8 -> 0 | CF13: =CD13*CE13 -> 0 | CH13: =CD13*$CH$8 -> 0 | CI13: =CE13*$CI$8 -> 0 | CJ13: =CH13*CI13 -> 0 | CL13: =CH13*$CL$8 -> 0 | CM13: =CI13*$CM$8 -> 0 | CN13: =CL13*CM13 -> 0 | CP13: =CL13*$CP$8 -> 0 | CQ13: =CM13*$CQ$8 -> 0 | CR13: =CP13*CQ13 -> 0 | CT13: =CP13*$CT$8 -> 0 | CU13: =CQ13*$CU$8 -> 0 | CV13: =CT13*CU13 -> 0 | CX13: =CT13*$CX$8 -> 0 | CY13: =CU13*$CY$8 -> 0 | CZ13: =CX13*CY13 -> 0 | DB13: =CX13*$DB$8 -> 0 | DC13: =CY13*$DC$8 -> 0 | DD13: =DB13*DC13 -> 0 | DF13: =DB13*$DF$8 -> 0 | DG13: =DC13*$DG$8 -> 0 | DH13: =DF13*DG13 -> 0 | DJ13: =DF13*$DJ$8 -> 0 | DK13: =DG13*$DK$8 -> 0 | DL13: =DJ13*DK13 -> 0 | DN13: =DJ13*$DN$8 -> 0 | DO13: =DK13*$DO$8 -> 0 | DP13: =DN13*DO13 -> 0 | DR13: =DN13*$DR$8 -> 0 | DS13: =DO13*$DS$8 -> 0 | DT13: =DR13*DS13 -> 0 | DV13: =DR13*$DV$8 -> 0 | DW13: =DS13*$DW$8 -> 0 | DX13: =DV13*DW13 -> 0 | DZ13: =DV13*$DZ$8 -> 0 | EA13: =DW13*$EA$8 -> 0 | EB13: =DZ13*EA13 -> 0 | ED13: =DZ13*$ED$8 -> 0 | EE13: =EA13*$EE$8 -> 0 | EF13: =ED13*EE13 -> 0 | EH13: =ED13*$EH$8 -> 0 | EI13: =EE13*$EI$8 -> 0 | EJ13: =EH13*EI13 -> 0 | EL13: =EH13*$EL$8 -> 0 | EM13: =EI13*$EM$8 -> 0 | EN13: =EL13*EM13 -> 0 | EP13: =EL13*$EP$8 -> 0 | EQ13: =EM13*$EQ$8 -> 0 | ER13: =EP13*EQ13 -> 0 | ET13: =EP13*$ET$8 -> 0 | EU13: =EQ13*$EU$8 -> 0 | EV13: =ET13*EU13 -> 0 | EX13: =ET13*$EX$8 -> 0 | EY13: =EU13*$EY$8 -> 0 | EZ13: =EX13*EY13 -> 0 | FB13: =EX13*$FB$8 -> 0 | FC13: =EY13*$FC$8 -> 0 | FD13: =FB13*FC13 -> 0 | FF13: =FB13*$FF$8 -> 0 | FG13: =FC13*$FG$8 -> 0 | FH13: =FF13*FG13 -> 0 | FJ13: =FF13*$FJ$8 -> 0 | FK13: =FG13*$FK$8 -> 0 | FL13: =FJ13*FK13 -> 0 | FN13: =FJ13*$FN$8 -> 0 | FO13: =FK13*$FO$8 -> 0 | FP13: =FN13*FO13 -> 0 | FR13: =FN13*$FR$8 -> 0 | FS13: =FO13*$FS$8 -> 0 | FT13: =FR13*FS13 -> 0 | FV13: =FR13*$FV$8 -> 0 | FW13: =FS13*$FW$8 -> 0 | FX13: =FV13*FW13 -> 0 | FZ13: =FV13*$FZ$8 -> 0 | GA13: =FW13*$GA$8 -> 0 | GB13: =FZ13*GA13 -> 0 | GD13: =FZ13*$GD$8 -> 0 | GE13: =GA13*$GE$8 -> 0 | GF13: =GD13*GE13 -> 0 | GH13: =GD13*$GH$8 -> 0 | GI13: =GE13*$GI$8 -> 0 | GJ13: =GH13*GI13 -> 0 | GL13: =GH13*$GL$8 -> 0 | GM13: =GI13*$GM$8 -> 0 | GN13: =GL13*GM13 -> 0 | GP13: =GL13*$GP$8 -> 0 | GQ13: =GM13*$GQ$8 -> 0 | GR13: =GP13*GQ13 -> 0 | GT13: =GP13*$GT$8 -> 0 | GU13: =GQ13*$GU$8 -> 0 | GV13: =GT13*GU13 -> 0 | GX13: =GT13*$GX$8 -> 0 | GY13: =GU13*$GY$8 -> 0 | GZ13: =GX13*GY13 -> 0 | HB13: =GX13*$HB$8 -> 0 | HC13: =GY13*$HC$8 -> 0 | HD13: =HB13*HC13 -> 0 | HF13: =HB13*$HF$8 -> 0 | HG13: =HC13*$HG$8 -> 0 | HH13: =HF13*HG13 -> 0 | HJ13: =HF13*$HJ$8 -> 0 | HK13: =HG13*$HK$8 -> 0 | HL13: =HJ13*HK13 -> 0 | HN13: =HJ13*$HN$8 -> 0 | HO13: =HK13*$HO$8 -> 0 | HP13: =HN13*HO13 -> 0 | HR13: =HN13*$HR$8 -> 0 | HS13: =HO13*$HS$8 -> 0 | HT13: =HR13*HS13 -> 0 | HV13: =HR13*$HV$8 -> 0 | HW13: =HS13*$HW$8 -> 0 | HX13: =HV13*HW13 -> 0 | HZ13: =HV13*$HZ$8 -> 0 | IA13: =HW13*$IA$8 -> 0 | IB13: =HZ13*IA13 -> 0 | ID13: =HZ13*$ID$8 -> 0 | IE13: =IA13*$IE$8 -> 0 | IF13: =ID13*IE13 -> 0 | IH13: =ID13*$IH$8 -> 0 | II13: =IE13*$II$8 -> 0 | IJ13: =IH13*II13 -> 0 | IL13: =SUMIFS($F13:$IK13,$F$3:$IK$3,IL$5,$F$6:$IK$6,IL$6) -> 0 | IM13: 0 | IN13: =SUMIFS($F13:$IK13,$F$3:$IK$3,IL$5,$F$6:$IK$6,IN$6) -> 0 | IP13: =SUMIFS($F13:$IK13,$F$3:$IK$3,IP$5,$F$6:$IK$6,IP$6) -> 0 | IQ13: 0 | IR13: =SUMIFS($F13:$IK13,$F$3:$IK$3,IP$5,$F$6:$IK$6,IR$6) -> 0 | IT13: =SUMIFS($F13:$IK13,$F$3:$IK$3,IT$5,$F$6:$IK$6,IT$6) -> 0 | IU13: 0 | IV13: =SUMIFS($F13:$IK13,$F$3:$IK$3,IT$5,$F$6:$IK$6,IV$6) -> 0 | IX13: =SUMIFS($F13:$IK13,$F$3:$IK$3,IX$5,$F$6:$IK$6,IX$6) -> 0 | IY13: 0 | IZ13: =SUMIFS($F13:$IK13,$F$3:$IK$3,IX$5,$F$6:$IK$6,IZ$6) -> 0 | JB13: =SUMIFS($F13:$IK13,$F$3:$IK$3,JB$5,$F$6:$IK$6,JB$6) -> 0 | JC13: 0 | JD13: =SUMIFS($F13:$IK13,$F$3:$IK$3,JB$5,$F$6:$IK$6,JD$6) -> 0 | JF13: =SUMIFS($F13:$IK13,$F$3:$IK$3,JF$5,$F$6:$IK$6,JF$6) -> 0 | JG13: 0 | JH13: =SUMIFS($F13:$IK13,$F$3:$IK$3,JF$5,$F$6:$IK$6,JH$6) -> 0
